Workbook

Sheet Jan 26
A1: Customer | B1: Q Number | C1: Region | D1: Payment Date | E1: Production Start Day | F1: Stage | G1: DEPOSIT | H1: FINAL | I1: TOTAL | J1: BOM Dep | K1: Dep to Rev | L1: New Dep this Month
A2: Advanced Windows:Golden Hill | B2: 84541 | C2: MD-C | D2: 45943 | E2: =VLOOKUP(B2,'[2]Month Total'!$B:$E,4,FALSE) -> Pre-Production | F2: =VLOOKUP(B2,'[2]Month Total'!$B:$F,5,FALSE) -> Pre-Production | G2: 10262 | H2: =I2-G2 -> 9172 | I2: 19434 | J2: 10262 | K2: =IF(G2=0,J2-G2,0) -> 0 | L2: =IF(G2>0,G2-J2,"Invoiced this Month") -> 0
A3: Akis Doganis:Doganis Residence | B3: 87185 | C3: NV-R | D3: 12/04/2025 | E3: =VLOOKUP(B3,'[2]Month Total'!$B:$E,4,FALSE) -> Pre-Production | F3: =VLOOKUP(B3,'[2]Month Total'!$B:$F,5,FALSE) -> Pre-Production | G3: 31515 | H3: =I3-G3 -> 31514 | I3: 63029 | J3: 31515 | K3: =IF(G3=0,J3-G3,0) -> 0 | L3: =IF(G3>0,G3-J3,"Invoiced this Month") -> 0
A4: All New Glass:201 Fillmore | B4: 78377 | C4: WA-C | D4: 02/24/2025 | E4: =VLOOKUP(B4,'[2]Month Total'!$B:$E,4,FALSE) -> 46007 | F4: =VLOOKUP(B4,'[2]Month Total'!$B:$F,5,FALSE) -> Powder coat | G4: 342623.5 | H4: =I4-G4 -> 342623.5 | I4: 685247 | J4: 342623.5 | K4: =IF(G4=0,J4-G4,0) -> 0 | L4: =IF(G4>0,G4-J4,"Invoiced this Month") -> 0
A5: All New Glass:201 Fillmore 1st Floor | B5: 86050 | C5: WA-C | D5: 45954 | E5: 46050 | F5: =VLOOKUP(B5,'[2]Month Total'!$B:$F,5,FALSE) -> Pre-Production | G5: 68086 | H5: =I5-G5 -> 67560 | I5: 135646 | J5: 34043 | K5: =IF(G5=0,J5-G5,0) -> 0 | L5: =IF(G5>0,G5-J5,"Invoiced this Month") -> 34043
A6: All New Glass:Chanel UTC | B6: 83846 | C6: WA-C | D6: 45880 | E6: =VLOOKUP(B6,'[2]Month Total'!$B:$E,4,FALSE) -> Pre-Production | F6: =VLOOKUP(B6,'[2]Month Total'!$B:$F,5,FALSE) -> Pre-Production | G6: 77743 | H6: =I6-G6 -> 77742 | I6: 155485 | J6: 77743 | K6: =IF(G6=0,J6-G6,0) -> 0 | L6: =IF(G6>0,G6-J6,"Invoiced this Month") -> 0
A7: American Glass - Livermore:Sunset Clubhouse-2 | B7: 85639 | C7: CA-C | D7: 45805 | E7: =VLOOKUP(B7,'[2]Month Total'!$B:$E,4,FALSE) -> 46015 | F7: =VLOOKUP(B7,'[2]Month Total'!$B:$F,5,FALSE) -> Pull Material | G7: 11673 | H7: =I7-G7 -> 11672 | I7: 23345 | J7: 11673 | K7: =IF(G7=0,J7-G7,0) -> 0 | L7: =IF(G7>0,G7-J7,"Invoiced this Month") -> 0
A8: American Products Inc (API):Lululemon Boston | B8: 86924 | C8: NA-C | D8: 45965 | E8: =VLOOKUP(B8,'[2]Month Total'!$B:$E,4,FALSE) -> 46013 | F8: =VLOOKUP(B8,'[2]Month Total'!$B:$F,5,FALSE) -> Powder coat | G8: 40090 | H8: =I8-G8 -> 40089 | I8: 80179 | J8: 40090 | K8: =IF(G8=0,J8-G8,0) -> 0 | L8: =IF(G8>0,G8-J8,"Invoiced this Month") -> 0
A9: Aragon Construction, Inc.:Penta (1) Interior | B9: 84044 | C9: CA-C | D9: 45811 | E9: =VLOOKUP(B9,'[2]Month Total'!$B:$E,4,FALSE) -> 46002 | F9: =VLOOKUP(B9,'[2]Month Total'!$B:$F,5,FALSE) -> Coating | G9: 93528 | H9: =I9-G9 -> -28848 | I9: 64680 | J9: 93528 | K9: =IF(G9=0,J9-G9,0) -> 0 | L9: =IF(G9>0,G9-J9,"Invoiced this Month") -> 0
A10: Aragon Construction, Inc.:Penta (2) Exterior | B10: 84046 | C10: CA-C | D10: 45811 | E10: =VLOOKUP(B10,'[2]Month Total'!$B:$E,4,FALSE) -> 46002 | F10: =VLOOKUP(B10,'[2]Month Total'!$B:$F,5,FALSE) -> Coating | G10: 97035 | H10: =I10-G10 -> 38165 | I10: 135200 | J10: 97035 | K10: =IF(G10=0,J10-G10,0) -> 0 | L10: =IF(G10>0,G10-J10,"Invoiced this Month") -> 0
A11: Aragon Construction, Inc.:Puente Hills | B11: 82690 | C11: CA-C | D11: 11/17/2025 | E11: =VLOOKUP(B11,'[2]Month Total'!$B:$E,4,FALSE) -> Pre-Production | F11: =VLOOKUP(B11,'[2]Month Total'!$B:$F,5,FALSE) -> Pre-Production | G11: 13744 | H11: =I11-G11 -> 12649 | I11: 26393 | J11: 13744 | K11: =IF(G11=0,J11-G11,0) -> 0 | L11: =IF(G11>0,G11-J11,"Invoiced this Month") -> 0
A12: Avatar Design Build LLC:Avatar Custom Home | B12: 84790 | C12: MD-R | D12: 45890 | E12: =VLOOKUP(B12,'[2]Month Total'!$B:$E,4,FALSE) -> 45973 | F12: =VLOOKUP(B12,'[2]Month Total'!$B:$F,5,FALSE) -> Powder coat | G12: 37869 | H12: =I12-G12 -> 37868 | I12: 75737 | J12: 37869 | K12: =IF(G12=0,J12-G12,0) -> 0 | L12: =IF(G12>0,G12-J12,"Invoiced this Month") -> 0
A13: Barbara Bellio:Bellio Residence | B13: 87402 | C13: NV-R | D13: 45939 | E13: =VLOOKUP(B13,'[2]Month Total'!$B:$E,4,FALSE) -> Pre-Production | F13: =VLOOKUP(B13,'[2]Month Total'!$B:$F,5,FALSE) -> Pre-Production | G13: 20000 | H13: =I13-G13 -> 19516 | I13: 39516 | J13: 20000 | K13: =IF(G13=0,J13-G13,0) -> 0 | L13: =IF(G13>0,G13-J13,"Invoiced this Month") -> 0
A14: Best Contracting LLC:UCSB San Benito Housing | B14: 87022 | C14: CA-C | D14: 11/20/2025 | E14: =VLOOKUP(B14,'[2]Month Total'!$B:$E,4,FALSE) -> Pre-Production | F14: =VLOOKUP(B14,'[2]Month Total'!$B:$F,5,FALSE) -> Pre-Production | G14: 60823 | H14: =I14-G14 -> 60822 | I14: 121645 | J14: 60823 | K14: =IF(G14=0,J14-G14,0) -> 0 | L14: =IF(G14>0,G14-J14,"Invoiced this Month") -> 0
A15: Biery Cheese Company:Silo Radius | B15: 87104 | C15: OH-C | D15: 45939 | E15: =VLOOKUP(B15,'[2]Month Total'!$B:$E,4,FALSE) -> Pre-Production | F15: =VLOOKUP(B15,'[2]Month Total'!$B:$F,5,FALSE) -> Pre-Production | G15: 24528.82 | H15: =I15-G15 -> 0 | I15: 24528.82 | J15: 24528.82 | K15: =IF(G15=0,J15-G15,0) -> 0 | L15: =IF(G15>0,G15-J15,"Invoiced this Month") -> 0
A16: BMG Door & Glass:Zamora Residence | B16: 88921 | C16: NV-R | D16: 01/30/2026 | E16: Pre-Production | F16: Pre-Production | G16: 18436 | H16: =I16-G16 -> 18436 | I16: 36872 | J16: 0 | L16: =IF(G16>0,G16-J16,"Invoiced this Month") -> 18436
A17: Builders Direct Supply:4545 North-Studio | B17: 85791 | C17: CA-R | D17: 45959 | E17: =VLOOKUP(B17,'[2]Month Total'!$B:$E,4,FALSE) -> Pre-Production | F17: =VLOOKUP(B17,'[2]Month Total'!$B:$F,5,FALSE) -> Pre-Production | G17: 8977.7 | H17: =I17-G17 -> 80799.3 | I17: 89777 | J17: 8977.7 | K17: =IF(G17=0,J17-G17,0) -> 0 | L17: =IF(G17>0,G17-J17,"Invoiced this Month") -> 0
A18: Builders Direct Supply:Direct Doors | B18: 87898 | C18: CA-R | D18: 45967 | E18: =VLOOKUP(B18,'[2]Month Total'!$B:$E,4,FALSE) -> 46000 | F18: =VLOOKUP(B18,'[2]Month Total'!$B:$F,5,FALSE) -> Coating | G18: 6997.5 | H18: =I18-G18 -> 6997.5 | I18: 13995 | J18: 6997.5 | K18: =IF(G18=0,J18-G18,0) -> 0 | L18: =IF(G18>0,G18-J18,"Invoiced this Month") -> 0
A19: Builders Direct Supply:North 4545 | B19: 83690 | C19: CA-R | D19: 45959 | E19: =VLOOKUP(B19,'[2]Month Total'!$B:$E,4,FALSE) -> Pre-Production | F19: =VLOOKUP(B19,'[2]Month Total'!$B:$F,5,FALSE) -> Pre-Production | G19: 41681.4 | H19: =I19-G19 -> 375132.6 | I19: 416814 | J19: 41681.4 | K19: =IF(G19=0,J19-G19,0) -> 0 | L19: =IF(G19>0,G19-J19,"Invoiced this Month") -> 0
A20: Builders Direct Supply:Snell and Wilmer | B20: 86318 | C20: CA-C | D20: 01/08/2026 | E20: Pre-Production | F20: Pre-Production | G20: 26483.5 | H20: =I20-G20 -> 26483.5 | I20: 52967 | J20: 0 | L20: =IF(G20>0,G20-J20,"Invoiced this Month") -> 26483.5
A21: Builders FirstSource/Dixieline Lumber & Home Center:Jody Doors | B21: 88100 | C21: CA-R | D21: 12/29/2025 | E21: =VLOOKUP(B21,'[2]Month Total'!$B:$E,4,FALSE) -> Pre-Production | F21: =VLOOKUP(B21,'[2]Month Total'!$B:$F,5,FALSE) -> Pre-Production | G21: 8674 | H21: =I21-G21 -> 8673 | I21: 17347 | J21: 8674 | K21: =IF(G21=0,J21-G21,0) -> 0 | L21: =IF(G21>0,G21-J21,"Invoiced this Month") -> 0
A22: Bulldog Diversified Construction:Bulldog Folding Door | B22: 88570 | C22: AZ-R | D22: 01/20/2026 | E22: Pre-Production | F22: Pre-Production | G22: 8743 | H22: =I22-G22 -> 8743 | I22: 17486 | J22: 0 | L22: =IF(G22>0,G22-J22,"Invoiced this Month") -> 8743
A23: C Thru Glass:Caesars Republic Pool Club Lounge | B23: 87633 | C23: NV-C | D23: 01/08/2026 | E23: Pre-Production | F23: Pre-Production | G23: 39028 | H23: =I23-G23 -> 39027 | I23: 78055 | J23: 0 | L23: =IF(G23>0,G23-J23,"Invoiced this Month") -> 39028
A24: Capitol Glass Company:99 Rhode Island | B24: 85440 | C24: CA-C | D24: 11/19/2025 | E24: 46044 | F24: =VLOOKUP(B24,'[2]Month Total'!$B:$F,5,FALSE) -> Pre-Production | G24: 15439 | H24: =I24-G24 -> 15438 | I24: 30877 | J24: 15439 | K24: =IF(G24=0,J24-G24,0) -> 0 | L24: =IF(G24>0,G24-J24,"Invoiced this Month") -> 0
A25: Capitol Glass Company:Sunnydale Block 7 | B25: 88227 | C25: CA-C | D25: 12/29/2025 | E25: =VLOOKUP(B25,'[2]Month Total'!$B:$E,4,FALSE) -> Pre-Production | F25: =VLOOKUP(B25,'[2]Month Total'!$B:$F,5,FALSE) -> Pre-Production | G25: 32005 | H25: =I25-G25 -> 32005 | I25: 64010 | J25: 32005 | K25: =IF(G25=0,J25-G25,0) -> 0 | L25: =IF(G25>0,G25-J25,"Invoiced this Month") -> 0
A26: Caribbean Windows International:Seagrapes 2 | B26: 87308 | C26: CAR-R | D26: 45918 | E26: =VLOOKUP(B26,'[2]Month Total'!$B:$E,4,FALSE) -> 45996 | F26: =VLOOKUP(B26,'[2]Month Total'!$B:$F,5,FALSE) -> Powder coat | G26: 57207 | H26: =I26-G26 -> 57327 | I26: 114534 | J26: 57207 | K26: =IF(G26=0,J26-G26,0) -> 0 | L26: =IF(G26>0,G26-J26,"Invoiced this Month") -> 0
A27: Castle House Distributors Inc.:Nila Bugala Door | B27: 88130 | C27: CA-R | D27: 11/24/2025 | E27: =VLOOKUP(B27,'[2]Month Total'!$B:$E,4,FALSE) -> 46000 | F27: 46045 | G27: 0 | J27: 7472.5 | K27: =IF(G27=0,J27-G27,0) -> 7472.5 | L27: =IF(G27>0,G27-J27,"Invoiced this Month") -> Invoiced this Month
A28: Catalyst Acoustics Group | B28: Unknown | D28: 05/31/2022 | E28: =VLOOKUP(B28,'[2]Month Total'!$B:$E,4,FALSE) -> Pre-Production | F28: =VLOOKUP(B28,'[2]Month Total'!$B:$F,5,FALSE) -> Pre-Production | G28: 4108 | H28: =I28-G28 -> 0 | I28: 4108 | J28: 4108 | K28: =IF(G28=0,J28-G28,0) -> 0 | L28: =IF(G28>0,G28-J28,"Invoiced this Month") -> 0
A29: Cheryl Partee:Partee Residence | B29: 86866 | C29: CA-R | D29: 11/25/2025 | E29: =VLOOKUP(B29,'[2]Month Total'!$B:$E,4,FALSE) -> 46015 | F29: =VLOOKUP(B29,'[2]Month Total'!$B:$F,5,FALSE) -> Powder coat | G29: 12000 | H29: =I29-G29 -> 10694 | I29: 22694 | J29: 12000 | K29: =IF(G29=0,J29-G29,0) -> 0 | L29: =IF(G29>0,G29-J29,"Invoiced this Month") -> 0
A30: Classic Carpentry Inc.:CC Project / 262 Mermaid's Bight | B30: 88131 | C30: FL-R | D30: 01/20/2026 | E30: Pre-Production | F30: Pre-Production | G30: 33237 | H30: =I30-G30 -> 33236 | I30: 66473 | J30: 0 | L30: =IF(G30>0,G30-J30,"Invoiced this Month") -> 33237
A31: Coltin Craigo:Alphorn Road | B31: 87218 | C31: WI-R | D31: 12/19/2025 | E31: 46028 | F31: =VLOOKUP(B31,'[2]Month Total'!$B:$F,5,FALSE) -> Pre-Production | G31: 7433 | H31: =I31-G31 -> 7432 | I31: 14865 | J31: 7433 | K31: =IF(G31=0,J31-G31,0) -> 0 | L31: =IF(G31>0,G31-J31,"Invoiced this Month") -> 0
A32: Constructa:Nuevo Proyecto en Punta Mita | B32: 83937 | C32: MX-C | D32: 11/20/2025 | E32: =VLOOKUP(B32,'[2]Month Total'!$B:$E,4,FALSE) -> Pre-Production | F32: =VLOOKUP(B32,'[2]Month Total'!$B:$F,5,FALSE) -> Pre-Production | G32: 59570.5 | H32: =I32-G32 -> 59590.5 | I32: 119161 | J32: 59570.5 | K32: =IF(G32=0,J32-G32,0) -> 0 | L32: =IF(G32>0,G32-J32,"Invoiced this Month") -> 0
A33: Crystal Glass Inc.:New Logan Elementry | B33: 83108 | C33: MI-C | D33: 04/17/2025 | E33: =VLOOKUP(B33,'[2]Month Total'!$B:$E,4,FALSE) -> Pre-Production | F33: =VLOOKUP(B33,'[2]Month Total'!$B:$F,5,FALSE) -> Pre-Production | G33: 172204.5 | H33: =I33-G33 -> 172204.5 | I33: 344409 | J33: 172204.5 | K33: =IF(G33=0,J33-G33,0) -> 0 | L33: =IF(G33>0,G33-J33,"Invoiced this Month") -> 0
A34: D & R Glass:Cedar and Sage | B34: 84134 | C34: CA-C | D34: 45945 | E34: =VLOOKUP(B34,'[2]Month Total'!$B:$E,4,FALSE) -> Pre-Production | F34: =VLOOKUP(B34,'[2]Month Total'!$B:$F,5,FALSE) -> Pre-Production | G34: 64205 | H34: =I34-G34 -> 61477 | I34: 125682 | J34: 64205 | K34: =IF(G34=0,J34-G34,0) -> 0 | L34: =IF(G34>0,G34-J34,"Invoiced this Month") -> 0
A35: D&A Glass:Camas Grill T.I. | B35: 87768 | C35: ID-C | D35: 45971 | E35: =VLOOKUP(B35,'[2]Month Total'!$B:$E,4,FALSE) -> 46000 | F35: =VLOOKUP(B35,'[2]Month Total'!$B:$F,5,FALSE) -> Coating | G35: 25537 | H35: =I35-G35 -> 25537 | I35: 51074 | J35: 25537 | K35: =IF(G35=0,J35-G35,0) -> 0 | L35: =IF(G35>0,G35-J35,"Invoiced this Month") -> 0
A36: D&A Glass:Turf Club | B36: 87822 | C36: ID-C | D36: 11/24/2025 | E36: =VLOOKUP(B36,'[2]Month Total'!$B:$E,4,FALSE) -> 46001 | F36: =VLOOKUP(B36,'[2]Month Total'!$B:$F,5,FALSE) -> Powder coat | G36: 115956 | H36: =I36-G36 -> 126839 | I36: 242795 | J36: 115956 | K36: =IF(G36=0,J36-G36,0) -> 0 | L36: =IF(G36>0,G36-J36,"Invoiced this Month") -> 0
A37: Danco Group:4441 N Jokake House | B37: 86461 | C37: AZ-R | D37: 45960 | E37: =VLOOKUP(B37,'[2]Month Total'!$B:$E,4,FALSE) -> Pre-Production | F37: Canceled 1/14 | G37: 0 | J37: 199193 | K37: =IF(G37=0,J37-G37,0) -> 199193 | L37: =IF(G37>0,G37-J37,"Invoiced this Month") -> Invoiced this Month
A38: Danco Group:4441 N Jokake Lift and Slide | B38: 86656 | C38: AZ-R | D38: 45890 | E38: =VLOOKUP(B38,'[2]Month Total'!$B:$E,4,FALSE) -> Pre-Production | F38: Canceled 1/14 | G38: 0 | J38: 113144 | K38: =IF(G38=0,J38-G38,0) -> 113144 | L38: =IF(G38>0,G38-J38,"Invoiced this Month") -> Invoiced this Month
A39: David Shuldiner Inc:450 Lexington | B39: 83623 | C39: NY-C | D39: 45859 | E39: =VLOOKUP(B39,'[2]Month Total'!$B:$E,4,FALSE) -> 46020 | F39: =VLOOKUP(B39,'[2]Month Total'!$B:$F,5,FALSE) -> Pull Material | G39: 75227 | H39: =I39-G39 -> 75226 | I39: 150453 | J39: 75227 | K39: =IF(G39=0,J39-G39,0) -> 0 | L39: =IF(G39>0,G39-J39,"Invoiced this Month") -> 0
A40: Debbie Piliero:46 Upper Rd | B40: 87161 | C40: CA-R | D40: 45924 | E40: =VLOOKUP(B40,'[2]Month Total'!$B:$E,4,FALSE) -> 45992 | F40: =VLOOKUP(B40,'[2]Month Total'!$B:$F,5,FALSE) -> Steel Job | G40: 17417 | H40: =I40-G40 -> 17417 | I40: 34834 | J40: 17417 | K40: =IF(G40=0,J40-G40,0) -> 0 | L40: =IF(G40>0,G40-J40,"Invoiced this Month") -> 0
...

Sheet Feb 26
A1: Customer | B1: Q Number | C1: Region | D1: Payment Date | E1: Production Start Day | F1: Stage | G1: DEPOSIT | H1: FINAL | I1: TOTAL | J1: BOM Dep | K1: Dep to Rev | L1: New Dep this Month
A2: Advanced Windows:1990 K Street | B2: 87616 | C2: MD-C | D2: 02/16/2026 | E2: Pre-Production | F2: Pre-Production | G2: 35586 | H2: =I2-G2 -> 9375 | I2: 44961 | J2: 0 | K2: =IF(G2=0,J2-G2,0) -> 0 | L2: =IF(G2>0,G2-J2,"Invoiced this Month") -> 35586
A3: Advanced Windows:Golden Hill | B3: 84541 | C3: MD-C | D3: 45943 | E3: Pre-Production | F3: Pre-Production | G3: 10262 | H3: =I3-G3 -> 10261 | I3: 20523 | J3: =VLOOKUP(A3,'Feb 26'!A:G,7,FALSE) -> 10262 | K3: =IF(G3=0,J3-G3,0) -> 0 | L3: =IF(G3>0,G3-J3,"Invoiced this Month") -> 0
A4: Akis Doganis:Doganis Residence | B4: 87185 | C4: NV-R | D4: 12/04/2025 | E4: Pre-Production | F4: Pre-Production | G4: 31515 | H4: =I4-G4 -> 31514 | I4: 63029 | J4: =VLOOKUP(A4,'Jan 26'!A:G,7,FALSE) -> 31515 | K4: =IF(G4=0,J4-G4,0) -> 0 | L4: =IF(G4>0,G4-J4,"Invoiced this Month") -> 0
A5: All New Glass:201 Fillmore | B5: 78377 | C5: WA-C | D5: 02/24/2025 | E5: 46007 | F5: Powder coat | G5: 342623.5 | H5: =I5-G5 -> 342623.5 | I5: 685247 | J5: =VLOOKUP(A5,'Jan 26'!A:G,7,FALSE) -> 342623.5 | K5: =IF(G5=0,J5-G5,0) -> 0 | L5: =IF(G5>0,G5-J5,"Invoiced this Month") -> 0
A6: All New Glass:201 Fillmore 1st Floor | B6: 86050 | C6: WA-C | D6: 45954 | E6: 46030 | F6: 46072 | G6: 0 | J6: =VLOOKUP(A6,'Jan 26'!A:G,7,FALSE) -> 68086 | K6: =IF(G6=0,J6-G6,0) -> 68086 | L6: =IF(G6>0,G6-J6,"Invoiced this Month") -> Invoiced this Month
A7: All New Glass:Chanel UTC | B7: 83846 | C7: WA-C | D7: 45880 | E7: 46076 | F7: Pre-Production | G7: =77743+30779.5 -> 108522.5 | H7: =I7-G7 -> 108521.5 | I7: 217044 | J7: =VLOOKUP(A7,'Jan 26'!A:G,7,FALSE) -> 77743 | K7: =IF(G7=0,J7-G7,0) -> 0 | L7: =IF(G7>0,G7-J7,"Invoiced this Month") -> 30779.5
A8: American Glass - Livermore:Sunset Clubhouse-2 | B8: 85639 | C8: CA-C | D8: 45805 | E8: 46015 | F8: Coating | G8: 11673 | H8: =I8-G8 -> 11672 | I8: 23345 | J8: =VLOOKUP(A8,'Jan 26'!A:G,7,FALSE) -> 11673 | K8: =IF(G8=0,J8-G8,0) -> 0 | L8: =IF(G8>0,G8-J8,"Invoiced this Month") -> 0
A9: American Products Inc (API):Lululemon Boston | B9: 86924 | C9: NA-C | D9: 45965 | E9: 46013 | F9: 46057 | G9: 0 | J9: =VLOOKUP(A9,'Jan 26'!A:G,7,FALSE) -> 40090 | K9: =IF(G9=0,J9-G9,0) -> 40090 | L9: =IF(G9>0,G9-J9,"Invoiced this Month") -> Invoiced this Month
A10: Aragon Construction, Inc.:Penta (1) Interior | B10: 84044 | C10: CA-C | D10: 45811 | E10: 46002 | F10: Cutting | G10: 93528 | H10: =I10-G10 -> -28848 | I10: 64680 | J10: =VLOOKUP(A10,'Jan 26'!A:G,7,FALSE) -> 93528 | K10: =IF(G10=0,J10-G10,0) -> 0 | L10: =IF(G10>0,G10-J10,"Invoiced this Month") -> 0
A11: Aragon Construction, Inc.:Penta (2) Exterior | B11: 84046 | C11: CA-C | D11: 45811 | E11: 46002 | F11: Cutting | G11: 97035 | H11: =I11-G11 -> 38165 | I11: 135200 | J11: =VLOOKUP(A11,'Jan 26'!A:G,7,FALSE) -> 97035 | K11: =IF(G11=0,J11-G11,0) -> 0 | L11: =IF(G11>0,G11-J11,"Invoiced this Month") -> 0
A12: Aragon Construction, Inc.:Puente Hills | B12: 82690 | C12: CA-C | D12: 11/17/2025 | E12: Pre-Production | F12: Pre-Production | G12: 13744 | H12: =I12-G12 -> 12649 | I12: 26393 | J12: =VLOOKUP(A12,'Jan 26'!A:G,7,FALSE) -> 13744 | K12: =IF(G12=0,J12-G12,0) -> 0 | L12: =IF(G12>0,G12-J12,"Invoiced this Month") -> 0
A13: Avatar Design Build LLC:Avatar Custom Home | B13: 84790 | C13: MD-R | D13: 45890 | E13: 45973 | F13: 46069 | G13: 0 | J13: =VLOOKUP(A13,'Jan 26'!A:G,7,FALSE) -> 37869 | K13: =IF(G13=0,J13-G13,0) -> 37869 | L13: =IF(G13>0,G13-J13,"Invoiced this Month") -> Invoiced this Month
A14: Barbara Bellio:Bellio Residence | B14: 87402 | C14: NV-R | D14: 45939 | E14: Pre-Production | F14: Pre-Production | G14: 20000 | H14: =I14-G14 -> 19516 | I14: 39516 | J14: =VLOOKUP(A14,'Jan 26'!A:G,7,FALSE) -> 20000 | K14: =IF(G14=0,J14-G14,0) -> 0 | L14: =IF(G14>0,G14-J14,"Invoiced this Month") -> 0
A15: Best Contracting LLC:UCSB San Benito Housing | B15: 87022 | C15: CA-C | D15: 11/20/2025 | E15: Pre-Production | F15: Pre-Production | G15: 60823 | H15: =I15-G15 -> 60822 | I15: 121645 | J15: =VLOOKUP(A15,'Jan 26'!A:G,7,FALSE) -> 60823 | K15: =IF(G15=0,J15-G15,0) -> 0 | L15: =IF(G15>0,G15-J15,"Invoiced this Month") -> 0
A16: Biery Cheese Company:Silo Radius | B16: 87104 | C16: OH-C | D16: 45939 | E16: 46072 | F16: Pre-Production | G16: 24528.82 | H16: =I16-G16 -> 0 | I16: 24528.82 | J16: =VLOOKUP(A16,'Jan 26'!A:G,7,FALSE) -> 24528.82 | K16: =IF(G16=0,J16-G16,0) -> 0 | L16: =IF(G16>0,G16-J16,"Invoiced this Month") -> 0
A17: BMG Door & Glass:Rowley | B17: 88961 | C17: AZ-R | D17: 46062 | E17: Pre-Production | F17: Pre-Production | G17: 22865 | H17: =I17-G17 -> 22864 | I17: 45729 | J17: 0 | K17: =IF(G17=0,J17-G17,0) -> 0 | L17: =IF(G17>0,G17-J17,"Invoiced this Month") -> 22865
A18: BMG Door & Glass:Zamora Residence | B18: 88921 | C18: NV-R | D18: 01/30/2026 | E18: Pre-Production | F18: Pre-Production | G18: 18436 | H18: =I18-G18 -> 18436 | I18: 36872 | J18: =VLOOKUP(A18,'Jan 26'!A:G,7,FALSE) -> 18436 | L18: =IF(G18>0,G18-J18,"Invoiced this Month") -> 0
A19: Brad Lager:Palmer | B19: 87591 | C19: MO-R | D19: 46058 | E19: Pre-Production | F19: Pre-Production | G19: 25317 | H19: =I19-G19 -> 25316 | I19: 50633 | J19: 0 | K19: =IF(G19=0,J19-G19,0) -> 0 | L19: =IF(G19>0,G19-J19,"Invoiced this Month") -> 25317
A20: Brett Hill Construction, Inc:4895 Kalanianaole | B20: 88674 | C20: HI-R | D20: 46055 | E20: Pre-Production | F20: Pre-Production | G20: 238760 | H20: =I20-G20 -> 238759 | I20: 477519 | J20: 0 | K20: =IF(G20=0,J20-G20,0) -> 0 | L20: =IF(G20>0,G20-J20,"Invoiced this Month") -> 238760
A21: Builders Direct Supply:4545 North-Studio | B21: 85791 | C21: CA-R | D21: 45959 | E21: Pre-Production | F21: Pre-Production | G21: 8977.7 | H21: =I21-G21 -> 80799.3 | I21: 89777 | J21: =VLOOKUP(A21,'Jan 26'!A:G,7,FALSE) -> 8977.7 | K21: =IF(G21=0,J21-G21,0) -> 0 | L21: =IF(G21>0,G21-J21,"Invoiced this Month") -> 0
A22: Builders Direct Supply:Direct Doors | B22: 87898 | C22: CA-R | D22: 45967 | E22: 46000 | F22: 46063 | G22: 0 | J22: =VLOOKUP(A22,'Jan 26'!A:G,7,FALSE) -> 6997.5 | K22: =IF(G22=0,J22-G22,0) -> 6997.5 | L22: =IF(G22>0,G22-J22,"Invoiced this Month") -> Invoiced this Month
A23: Builders Direct Supply:Larroque Door | B23: 88582 | C23: CA-R | D23: 02/16/2026 | E23: Pre-Production | F23: Pre-Production | G23: 4551 | H23: =I23-G23 -> 4551 | I23: 9102 | J23: 0 | K23: =IF(G23=0,J23-G23,0) -> 0 | L23: =IF(G23>0,G23-J23,"Invoiced this Month") -> 4551
A24: Builders Direct Supply:Marriott | B24: 88115 | C24: CA-C | D24: 46059 | E24: Pre-Production | F24: Pre-Production | G24: 62150.5 | H24: =I24-G24 -> 62150.5 | I24: 124301 | J24: 0 | K24: =IF(G24=0,J24-G24,0) -> 0 | L24: =IF(G24>0,G24-J24,"Invoiced this Month") -> 62150.5
A25: Builders Direct Supply:North 4545 | B25: 83690 | C25: CA-R | D25: 45959 | E25: Pre-Production | F25: Pre-Production | G25: 41681.4 | H25: =I25-G25 -> 375132.6 | I25: 416814 | J25: =VLOOKUP(A25,'Jan 26'!A:G,7,FALSE) -> 41681.4 | K25: =IF(G25=0,J25-G25,0) -> 0 | L25: =IF(G25>0,G25-J25,"Invoiced this Month") -> 0
A26: Builders Direct Supply:Snell and Wilmer | B26: 86318 | C26: CA-C | D26: 01/08/2026 | E26: Pre-Production | F26: Pre-Production | G26: 26483.5 | H26: =I26-G26 -> 26483.5 | I26: 52967 | J26: =VLOOKUP(A26,'Jan 26'!A:G,7,FALSE) -> 26483.5 | L26: =IF(G26>0,G26-J26,"Invoiced this Month") -> 0
A27: Builders FirstSource/Dixieline Lumber & Home Center:Jody Doors | B27: 88100 | C27: CA-R | D27: 12/29/2025 | E27: 46062 | F27: Pre-Production | G27: 8674 | H27: =I27-G27 -> 8673 | I27: 17347 | J27: =VLOOKUP(A27,'Jan 26'!A:G,7,FALSE) -> 8674 | K27: =IF(G27=0,J27-G27,0) -> 0 | L27: =IF(G27>0,G27-J27,"Invoiced this Month") -> 0
A28: Bulldog Diversified Construction:Bulldog Folding Door | B28: 88570 | C28: AZ-R | D28: 01/20/2026 | E28: 46055 | F28: 46077 | G28: 0 | J28: =VLOOKUP(A28,'Jan 26'!A:G,7,FALSE) -> 8743 | K28: =IF(G28=0,J28-G28,0) -> 8743 | L28: =IF(G28>0,G28-J28,"Invoiced this Month") -> Invoiced this Month
A29: C Thru Glass:Caesars Republic Pool Club Lounge | B29: 87633 | C29: NV-C | D29: 01/08/2026 | E29: 46072 | F29: Pre-Production | G29: 39028 | H29: =I29-G29 -> 39027 | I29: 78055 | J29: =VLOOKUP(A29,'Jan 26'!A:G,7,FALSE) -> 39028 | L29: =IF(G29>0,G29-J29,"Invoiced this Month") -> 0
A30: Capitol Glass & Aluminum Co.:Cypress Village | B30: 88240 | C30: FL-C | D30: 46062 | E30: Pre-Production | F30: Pre-Production | G30: 16435.5 | H30: =I30-G30 -> 16435.5 | I30: 32871 | J30: 0 | K30: =IF(G30=0,J30-G30,0) -> 0 | L30: =IF(G30>0,G30-J30,"Invoiced this Month") -> 16435.5
A31: Capitol Glass Company:99 Rhode Island | B31: 85440 | C31: CA-C | D31: 11/19/2025 | E31: 46044 | F31: Cutting | G31: 15439 | H31: =I31-G31 -> 15438 | I31: 30877 | J31: =VLOOKUP(A31,'Jan 26'!A:G,7,FALSE) -> 15439 | K31: =IF(G31=0,J31-G31,0) -> 0 | L31: =IF(G31>0,G31-J31,"Invoiced this Month") -> 0
A32: Capitol Glass Company:Sunnydale Block 7 | B32: 88227 | C32: CA-C | D32: 12/29/2025 | E32: Pre-Production | F32: Pre-Production | G32: 32005 | H32: =I32-G32 -> 32005 | I32: 64010 | J32: =VLOOKUP(A32,'Jan 26'!A:G,7,FALSE) -> 32005 | K32: =IF(G32=0,J32-G32,0) -> 0 | L32: =IF(G32>0,G32-J32,"Invoiced this Month") -> 0
A33: Caribbean Windows International:Seagrapes 2 | B33: 87308 | C33: CAR-R | D33: 45918 | E33: 45996 | F33: 46071 | G33: 0 | J33: =VLOOKUP(A33,'Jan 26'!A:G,7,FALSE) -> 57207 | K33: =IF(G33=0,J33-G33,0) -> 57207 | L33: =IF(G33>0,G33-J33,"Invoiced this Month") -> Invoiced this Month
A34: Catalyst Acoustics Group | B34: Unknown | D34: 05/31/2022 | E34: Pre-Production | F34: Pre-Production | G34: 4108 | H34: =I34-G34 -> 0 | I34: 4108 | J34: =VLOOKUP(A34,'Jan 26'!A:G,7,FALSE) -> 4108 | K34: =IF(G34=0,J34-G34,0) -> 0 | L34: =IF(G34>0,G34-J34,"Invoiced this Month") -> 0
A35: Cheryl Partee:Partee Residence | B35: 86866 | C35: CA-R | D35: 11/25/2025 | E35: 46015 | F35: 46072 | G35: 0 | J35: =VLOOKUP(A35,'Jan 26'!A:G,7,FALSE) -> 12000 | K35: =IF(G35=0,J35-G35,0) -> 12000 | L35: =IF(G35>0,G35-J35,"Invoiced this Month") -> Invoiced this Month
A36: Chris & Kareen Brown:By Woods Door | B36: 86825 | C36: MD-R | D36: 02/23/2026 | E36: Pre-Production | F36: Pre-Production | G36: 6409 | H36: =I36-G36 -> 6408 | I36: 12817 | J36: 0 | K36: =IF(G36=0,J36-G36,0) -> 0 | L36: =IF(G36>0,G36-J36,"Invoiced this Month") -> 6409
A37: CK2 Contracting:1221 W. Washington | B37: 88868 | C37: IL-R | D37: 46059 | E37: Pre-Production | F37: Pre-Production | G37: 17321 | H37: =I37-G37 -> 17321 | I37: 34642 | J37: 0 | K37: =IF(G37=0,J37-G37,0) -> 0 | L37: =IF(G37>0,G37-J37,"Invoiced this Month") -> 17321
A38: Classic Carpentry Inc.:CC Project / 262 Mermaid's Bight | B38: 88131 | C38: FL-R | D38: 01/20/2026 | E38: 46076 | F38: Pre-Production | G38: 33237 | H38: =I38-G38 -> 33236 | I38: 66473 | J38: =VLOOKUP(A38,'Jan 26'!A:G,7,FALSE) -> 33237 | L38: =IF(G38>0,G38-J38,"Invoiced this Month") -> 0
A39: Coltin Craigo:Alphorn Road | B39: 87218 | C39: WI-R | D39: 12/19/2025 | E39: 46028 | F39: Assembly | G39: 7433 | H39: =I39-G39 -> 7432 | I39: 14865 | J39: =VLOOKUP(A39,'Jan 26'!A:G,7,FALSE) -> 7433 | K39: =IF(G39=0,J39-G39,0) -> 0 | L39: =IF(G39>0,G39-J39,"Invoiced this Month") -> 0
A40: Constructa:Nuevo Proyecto en Punta Mita | B40: 83937 | C40: MX-C | D40: 11/20/2025 | E40: 46071 | F40: Pre-Production | G40: 59570.5 | H40: =I40-G40 -> 59590.5 | I40: 119161 | J40: =VLOOKUP(A40,'Jan 26'!A:G,7,FALSE) -> 59570.5 | K40: =IF(G40=0,J40-G40,0) -> 0 | L40: =IF(G40>0,G40-J40,"Invoiced this Month") -> 0
...

Sheet Mar 26
A1: Customer | B1: Q Number | C1: Region | D1: Payment Date | E1: Production Start Day | F1: Stage | G1: DEPOSIT | H1: FINAL | I1: TOTAL | J1: BOM Dep | K1: Dep to Rev | L1: New Dep this Month
A2: 1st Choice Glass:MUSC - Clemson | B2: 88562 | C2: NC-C | D2: 46091 | E2: Pre-Production | G2: 51110.14 | H2: =I2-G2 -> 0 | I2: 51110.14 | K2: =IF(G2=0,J2-G2,0) -> 0 | L2: =IF(G2>0,G2-J2,"Invoiced this Month") -> 51110.14 | M2: =L2-K2 -> 51110.14
A3: A&A Window Products Inc:45 Littles Road | B3: 88556 | C3: MA-R | D3: 46086 | E3: Pre-Production | G3: 11662 | H3: =I3-G3 -> 11662 | I3: 23324 | K3: =IF(G3=0,J3-G3,0) -> 0 | L3: =IF(G3>0,G3-J3,"Invoiced this Month") -> 11662 | M3: =L3-K3 -> 11662
A4: Advanced Windows:1990 K Street | B4: 87616 | C4: MD-C | D4: 02/16/2026 | E4: Pre-Production | F4: Pre-Production | G4: 35586 | H4: =I4-G4 -> 9375 | I4: 44961 | J4: =VLOOKUP(A4,'Feb 26'!A:G,7,FALSE) -> 35586 | K4: =IF(G4=0,J4-G4,0) -> 0 | L4: =IF(G4>0,G4-J4,"Invoiced this Month") -> 0 | M4: =L4-K4 -> 0
A5: Advanced Windows:Golden Hill | B5: 84541 | C5: MD-C | D5: 45943 | E5: Pre-Production | F5: Pre-Production | G5: 10262 | H5: =I5-G5 -> 10261 | I5: 20523 | J5: =VLOOKUP(A5,'Feb 26'!A:G,7,FALSE) -> 10262 | K5: =IF(G5=0,J5-G5,0) -> 0 | L5: =IF(G5>0,G5-J5,"Invoiced this Month") -> 0 | M5: =L5-K5 -> 0
A6: Ajay Glass & Mirror Co., Inc.:Billitier | B6: 89718 | C6: NY-R | D6: 46105 | E6: Pre-Production | G6: 9796.19 | H6: =I6-G6 -> 9796.18 | I6: 19592.37 | K6: =IF(G6=0,J6-G6,0) -> 0 | L6: =IF(G6>0,G6-J6,"Invoiced this Month") -> 9796.19 | M6: =L6-K6 -> 9796.19
A7: Akis Doganis:Doganis Residence | B7: 87185 | C7: NV-R | D7: 12/04/2025 | E7: Pre-Production | F7: Pre-Production | G7: 31515 | H7: =I7-G7 -> 31514 | I7: 63029 | J7: =VLOOKUP(A7,'Feb 26'!A:G,7,FALSE) -> 31515 | K7: =IF(G7=0,J7-G7,0) -> 0 | L7: =IF(G7>0,G7-J7,"Invoiced this Month") -> 0 | M7: =L7-K7 -> 0
A8: All New Glass:201 Fillmore | B8: 78377 | C8: WA-C | D8: 02/24/2025 | E8: 46007 | F8: 46093 | J8: =VLOOKUP(A8,'Feb 26'!A:G,7,FALSE) -> 342623.5 | K8: =IF(G8=0,J8-G8,0) -> 342623.5 | L8: =IF(G8>0,G8-J8,"Invoiced this Month") -> Invoiced this Month | M8: =-K8 -> -342623.5
A9: All New Glass:Chanel UTC | B9: 83846 | C9: WA-C | D9: 45880 | E9: 46076 | F9: Pre-Production | G9: =77743+30779.5 -> 108522.5 | H9: =I9-G9 -> 108521.5 | I9: 217044 | J9: =VLOOKUP(A9,'Feb 26'!A:G,7,FALSE) -> 108522.5 | K9: =IF(G9=0,J9-G9,0) -> 0 | L9: =IF(G9>0,G9-J9,"Invoiced this Month") -> 0 | M9: =L9-K9 -> 0
A10: Alli Construction:Chaparral Janiga Residence | B10: 89424 | C10: CA-R | D10: 46090 | E10: Pre-Production | G10: 16906.51 | H10: =I10-G10 -> 16906.5 | I10: 33813.01 | K10: =IF(G10=0,J10-G10,0) -> 0 | L10: =IF(G10>0,G10-J10,"Invoiced this Month") -> 16906.51 | M10: =L10-K10 -> 16906.51
A11: American Glass - Livermore:Sunset Clubhouse-2 | B11: 85639 | C11: CA-C | D11: 45805 | E11: 46015 | F11: 46097 | J11: =VLOOKUP(A11,'Feb 26'!A:G,7,FALSE) -> 11673 | K11: =IF(G11=0,J11-G11,0) -> 11673 | L11: =IF(G11>0,G11-J11,"Invoiced this Month") -> Invoiced this Month | M11: =-K11 -> -11673
A12: American Glass & Mirror Company:1000 Nevillewood Drive | B12: 87836 | C12: VA-C | D12: 46098 | E12: Pre-Production | G12: 18709 | H12: =I12-G12 -> 18709 | I12: 37418 | K12: =IF(G12=0,J12-G12,0) -> 0 | L12: =IF(G12>0,G12-J12,"Invoiced this Month") -> 18709 | M12: =L12-K12 -> 18709
A13: American Products Inc (API):LuLulemon Boston Panel | B13: 89707 | C13: FL-C | D13: 46107 | E13: Pre-Production | G13: 3227 | H13: =I13-G13 -> 3227 | I13: 6454 | K13: =IF(G13=0,J13-G13,0) -> 0 | L13: =IF(G13>0,G13-J13,"Invoiced this Month") -> 3227 | M13: =L13-K13 -> 3227
A14: Angie Nyborg:Nyborg Residence | B14: 89450 | C14: NV-R | D14: 46097 | E14: Pre-Production | G14: 29728 | H14: =I14-G14 -> 31453 | I14: 61181 | K14: =IF(G14=0,J14-G14,0) -> 0 | L14: =IF(G14>0,G14-J14,"Invoiced this Month") -> 29728 | M14: =L14-K14 -> 29728
A15: Aragon Construction, Inc.:Penta (1) Interior | B15: 84044 | C15: CA-C | D15: 45811 | E15: 46002 | F15: Cutting | G15: 93528 | H15: =I15-G15 -> -28848 | I15: 64680 | J15: =VLOOKUP(A15,'Feb 26'!A:G,7,FALSE) -> 93528 | K15: =IF(G15=0,J15-G15,0) -> 0 | L15: =IF(G15>0,G15-J15,"Invoiced this Month") -> 0 | M15: =L15-K15 -> 0
A16: Aragon Construction, Inc.:Penta (2) Exterior | B16: 84046 | C16: CA-C | D16: 45811 | E16: 46002 | F16: Cutting | G16: 97035 | H16: =I16-G16 -> 38165 | I16: 135200 | J16: =VLOOKUP(A16,'Feb 26'!A:G,7,FALSE) -> 97035 | K16: =IF(G16=0,J16-G16,0) -> 0 | L16: =IF(G16>0,G16-J16,"Invoiced this Month") -> 0 | M16: =L16-K16 -> 0
A17: Aragon Construction, Inc.:Puente Hills | B17: 82690 | C17: CA-C | D17: 11/17/2025 | E17: Pre-Production | F17: Pre-Production | G17: 13744 | H17: =I17-G17 -> 12649 | I17: 26393 | J17: =VLOOKUP(A17,'Feb 26'!A:G,7,FALSE) -> 13744 | K17: =IF(G17=0,J17-G17,0) -> 0 | L17: =IF(G17>0,G17-J17,"Invoiced this Month") -> 0 | M17: =L17-K17 -> 0
A18: Aune Brothers Construction:2460 Cajon Lane | B18: 86022 | C18: AZ-R | D18: 46091 | E18: Pre-Production | G18: 4247 | H18: =I18-G18 -> 4247 | I18: 8494 | K18: =IF(G18=0,J18-G18,0) -> 0 | L18: =IF(G18>0,G18-J18,"Invoiced this Month") -> 4247 | M18: =L18-K18 -> 4247
A19: Barbara Bellio:Bellio Residence | B19: 87402 | C19: NV-R | D19: 45939 | E19: Pre-Production | F19: Pre-Production | G19: 20000 | H19: =I19-G19 -> 19516 | I19: 39516 | J19: =VLOOKUP(A19,'Feb 26'!A:G,7,FALSE) -> 20000 | K19: =IF(G19=0,J19-G19,0) -> 0 | L19: =IF(G19>0,G19-J19,"Invoiced this Month") -> 0 | M19: =L19-K19 -> 0
A20: Best Contracting LLC:UCSB San Benito Housing | B20: 87022 | C20: CA-C | D20: 11/20/2025 | E20: Pre-Production | F20: Pre-Production | G20: 60823 | H20: =I20-G20 -> 60822 | I20: 121645 | J20: =VLOOKUP(A20,'Feb 26'!A:G,7,FALSE) -> 60823 | K20: =IF(G20=0,J20-G20,0) -> 0 | L20: =IF(G20>0,G20-J20,"Invoiced this Month") -> 0 | M20: =L20-K20 -> 0
A21: Biery Cheese Company:Silo Radius | B21: 87104 | C21: OH-C | D21: 45939 | E21: 46072 | F21: 46106 | J21: =VLOOKUP(A21,'Feb 26'!A:G,7,FALSE) -> 24528.82 | K21: =IF(G21=0,J21-G21,0) -> 24528.82 | L21: =IF(G21>0,G21-J21,"Invoiced this Month") -> Invoiced this Month | M21: =-K21 -> -24528.82
A22: BMG Door & Glass:Rowley | B22: 88961 | C22: AZ-R | D22: 46062 | E22: Pre-Production | F22: Pre-Production | G22: 22865 | H22: =I22-G22 -> 22864 | I22: 45729 | J22: =VLOOKUP(A22,'Feb 26'!A:G,7,FALSE) -> 22865 | K22: =IF(G22=0,J22-G22,0) -> 0 | L22: =IF(G22>0,G22-J22,"Invoiced this Month") -> 0 | M22: =L22-K22 -> 0
A23: BMG Door & Glass:Zamora Residence | B23: 88921 | C23: NV-R | D23: 01/30/2026 | E23: Pre-Production | F23: 46112 | J23: =VLOOKUP(A23,'Feb 26'!A:G,7,FALSE) -> 18436 | K23: =IF(G23=0,J23-G23,0) -> 18436 | L23: =IF(G23>0,G23-J23,"Invoiced this Month") -> Invoiced this Month | M23: =-K23 -> -18436
A24: Brad Lager:Palmer | B24: 87591 | C24: MO-R | D24: 46058 | E24: Pre-Production | F24: Pre-Production | G24: 25317 | H24: =I24-G24 -> 25316 | I24: 50633 | J24: =VLOOKUP(A24,'Feb 26'!A:G,7,FALSE) -> 25317 | K24: =IF(G24=0,J24-G24,0) -> 0 | L24: =IF(G24>0,G24-J24,"Invoiced this Month") -> 0 | M24: =L24-K24 -> 0
A25: Brett Hill Construction, Inc:4895 Kalanianaole | B25: 88674 | C25: HI-R | D25: 46055 | E25: Pre-Production | F25: Pre-Production | G25: 238760 | H25: =I25-G25 -> 238759 | I25: 477519 | J25: =VLOOKUP(A25,'Feb 26'!A:G,7,FALSE) -> 238760 | K25: =IF(G25=0,J25-G25,0) -> 0 | L25: =IF(G25>0,G25-J25,"Invoiced this Month") -> 0 | M25: =L25-K25 -> 0
A26: Builders Direct Supply:4545 North-Studio | B26: 85791 | C26: CA-R | D26: 45959 | E26: Pre-Production | F26: Pre-Production | G26: 8977.7 | H26: =I26-G26 -> 80799.3 | I26: 89777 | J26: =VLOOKUP(A26,'Feb 26'!A:G,7,FALSE) -> 8977.7 | K26: =IF(G26=0,J26-G26,0) -> 0 | L26: =IF(G26>0,G26-J26,"Invoiced this Month") -> 0 | M26: =L26-K26 -> 0
A27: Builders Direct Supply:Larroque Door | B27: 88582 | C27: CA-R | D27: 02/16/2026 | E27: Pre-Production | F27: 46112 | J27: =VLOOKUP(A27,'Feb 26'!A:G,7,FALSE) -> 4551 | K27: =IF(G27=0,J27-G27,0) -> 4551 | L27: =IF(G27>0,G27-J27,"Invoiced this Month") -> Invoiced this Month | M27: =-K27 -> -4551
A28: Builders Direct Supply:Marriott | B28: 88115 | C28: CA-C | D28: 46059 | E28: Pre-Production | F28: Pre-Production | G28: 62150.5 | H28: =I28-G28 -> 62150.5 | I28: 124301 | J28: =VLOOKUP(A28,'Feb 26'!A:G,7,FALSE) -> 62150.5 | K28: =IF(G28=0,J28-G28,0) -> 0 | L28: =IF(G28>0,G28-J28,"Invoiced this Month") -> 0 | M28: =L28-K28 -> 0
A29: Builders Direct Supply:North 4545 | B29: 83690 | C29: CA-R | D29: 45959 | E29: Pre-Production | F29: Pre-Production | G29: 41681.4 | H29: =I29-G29 -> 375132.6 | I29: 416814 | J29: =VLOOKUP(A29,'Feb 26'!A:G,7,FALSE) -> 41681.4 | K29: =IF(G29=0,J29-G29,0) -> 0 | L29: =IF(G29>0,G29-J29,"Invoiced this Month") -> 0 | M29: =L29-K29 -> 0
A30: Builders Direct Supply:Snell and Wilmer | B30: 86318 | C30: CA-C | D30: 01/08/2026 | E30: Pre-Production | F30: Pre-Production | G30: 26483.5 | H30: =I30-G30 -> 26483.5 | I30: 52967 | J30: =VLOOKUP(A30,'Feb 26'!A:G,7,FALSE) -> 26483.5 | L30: =IF(G30>0,G30-J30,"Invoiced this Month") -> 0 | M30: =L30-K30 -> 0
A31: Builders FirstSource/Dixieline Lumber & Home Center:Bhill Orange County | B31: 89482 | C31: CA-R | D31: 46111 | E31: Pre-Production | G31: 4138 | H31: =I31-G31 -> 4138 | I31: 8276 | K31: =IF(G31=0,J31-G31,0) -> 0 | L31: =IF(G31>0,G31-J31,"Invoiced this Month") -> 4138 | M31: =L31-K31 -> 4138
A32: Builders FirstSource/Dixieline Lumber & Home Center:Dixieline Lumber & Home Center:Rick Moore | B32: 89242 | C32: CA-C | D32: 46083 | E32: Pre-Production | G32: 8432 | H32: =I32-G32 -> 8432 | I32: 16864 | K32: =IF(G32=0,J32-G32,0) -> 0 | L32: =IF(G32>0,G32-J32,"Invoiced this Month") -> 8432 | M32: =L32-K32 -> 8432
A33: Builders FirstSource/Dixieline Lumber & Home Center:Jody Doors | B33: 88100 | C33: CA-R | D33: 12/29/2025 | E33: 46062 | F33: 46094 | J33: =VLOOKUP(A33,'Feb 26'!A:G,7,FALSE) -> 8674 | K33: =IF(G33=0,J33-G33,0) -> 8674 | L33: =IF(G33>0,G33-J33,"Invoiced this Month") -> Invoiced this Month | M33: =-K33 -> -8674
A34: C Thru Glass:Caesars Republic Pool Club Lounge | B34: 87633 | C34: NV-C | D34: 01/08/2026 | E34: 46072 | F34: 46108 | J34: =VLOOKUP(A34,'Feb 26'!A:G,7,FALSE) -> 39028 | K34: =IF(G34=0,J34-G34,0) -> 39028 | L34: =IF(G34>0,G34-J34,"Invoiced this Month") -> Invoiced this Month | M34: =-K34 -> -39028
A35: CAC Aluminum & Glass Inc.:355 Deerfield Sliding Doors | B35: 89649 | C35: IL-C | D35: 46101 | E35: Pre-Production | G35: 17176 | H35: =I35-G35 -> 17175 | I35: 34351 | K35: =IF(G35=0,J35-G35,0) -> 0 | L35: =IF(G35>0,G35-J35,"Invoiced this Month") -> 17176 | M35: =L35-K35 -> 17176
A36: Capitol Glass & Aluminum Co.:Cypress Village | B36: 88240 | C36: FL-C | D36: 46062 | E36: Pre-Production | F36: Pre-Production | G36: 16435.5 | H36: =I36-G36 -> 16435.5 | I36: 32871 | J36: =VLOOKUP(A36,'Feb 26'!A:G,7,FALSE) -> 16435.5 | K36: =IF(G36=0,J36-G36,0) -> 0 | L36: =IF(G36>0,G36-J36,"Invoiced this Month") -> 0 | M36: =L36-K36 -> 0
A37: Capitol Glass Company:99 Rhode Island | B37: 85440 | C37: CA-C | D37: 11/19/2025 | E37: 46044 | F37: 46106 | J37: =VLOOKUP(A37,'Feb 26'!A:G,7,FALSE) -> 15439 | K37: =IF(G37=0,J37-G37,0) -> 15439 | L37: =IF(G37>0,G37-J37,"Invoiced this Month") -> Invoiced this Month | M37: =-K37 -> -15439
A38: Capitol Glass Company:Sunnydale Block 7 | B38: 88227 | C38: CA-C | D38: 12/29/2025 | E38: Pre-Production | F38: Pre-Production | G38: 32005 | H38: =I38-G38 -> 32005 | I38: 64010 | J38: =VLOOKUP(A38,'Feb 26'!A:G,7,FALSE) -> 32005 | K38: =IF(G38=0,J38-G38,0) -> 0 | L38: =IF(G38>0,G38-J38,"Invoiced this Month") -> 0 | M38: =L38-K38 -> 0
A39: Capitol Glass Company:The Eliza | B39: 84966 | C39: CA-C | D39: 46099 | E39: Pre-Production | G39: 39804 | H39: =I39-G39 -> 39803 | I39: 79607 | K39: =IF(G39=0,J39-G39,0) -> 0 | L39: =IF(G39>0,G39-J39,"Invoiced this Month") -> 39804 | M39: =L39-K39 -> 39804
A40: Catalyst Acoustics Group | B40: Unknown | D40: 05/31/2022 | E40: Pre-Production | F40: Pre-Production | G40: 4108 | H40: =I40-G40 -> 0 | I40: 4108 | J40: =VLOOKUP(A40,'Feb 26'!A:G,7,FALSE) -> 4108 | K40: =IF(G40=0,J40-G40,0) -> 0 | L40: =IF(G40>0,G40-J40,"Invoiced this Month") -> 0 | M40: =L40-K40 -> 0
...

Sheet Apr 26
A1: Customer | B1: Q Number | C1: Region | D1: Payment Date | E1: Production Start Day | F1: Stage | G1: DEPOSIT | H1: FINAL | I1: TOTAL | J1: BOM Dep | K1: Dep to Rev | L1: New Dep this Month
A2: 1st Choice Glass:MUSC - Clemson | B2: 88562 | C2: NC-C | D2: 46091 | E2: Pre-Production | F2: Pre-Production | G2: 51110.14 | H2: 0 | I2: 51110.14 | J2: =IFERROR(VLOOKUP(B2,'Mar 26'!B:G,6,FALSE),0) -> 51110.14 | K2: 0 | L2: =G2-J2 -> 0 | M2: =L2-K2 -> 0
A3: A&A Window Products Inc:45 Littles Road | B3: 88556 | C3: MA-R | D3: 46086 | E3: Pre-Production | F3: Pre-Production | G3: 11662 | H3: 11662 | I3: 23324 | J3: =VLOOKUP(B3,'Mar 26'!B:G,6,FALSE) -> 11662 | K3: 0 | L3: =G3-J3 -> 0 | M3: =L3-K3 -> 0
A4: Advanced Windows:1990 K Street | B4: 87616 | C4: MD-C | D4: 46069 | E4: Pre-Production | F4: Pre-Production | G4: 35586 | H4: 9375 | I4: 44961 | J4: =VLOOKUP(B4,'Mar 26'!B:G,6,FALSE) -> 35586 | K4: 0 | L4: =G4-J4 -> 0 | M4: =L4-K4 -> 0
A5: Advanced Windows:Golden Hill | B5: 84541 | C5: MD-C | D5: 45943 | E5: 46083 | F5: Coating | G5: 10262 | H5: 10261 | I5: 20523 | J5: =VLOOKUP(B5,'Mar 26'!B:G,6,FALSE) -> 10262 | K5: 0 | L5: =G5-J5 -> 0 | M5: =L5-K5 -> 0
A6: AFR Construction:Boe Dekker | B6: 87676 | C6: NV-R | D6: 46125 | E6: Pre-Production | F6: Pre-Production | G6: 2400.25 | H6: =I6-G6 -> 2449.75 | I6: 4850 | J6: 0 | K6: 0 | L6: =G6-J6 -> 2400.25 | M6: =L6-K6 -> 2400.25
A7: Ajay Glass & Mirror Co., Inc.:Billitier | B7: 89718 | C7: NY-R | D7: 46105 | E7: Pre-Production | F7: Pre-Production | G7: 9796.19 | H7: 9796.18 | I7: 19592.37 | J7: =VLOOKUP(B7,'Mar 26'!B:G,6,FALSE) -> 9796.19 | K7: 0 | L7: =G7-J7 -> 0 | M7: =L7-K7 -> 0
A8: Akis Doganis:Doganis Residence | B8: 87185 | C8: NV-R | D8: 45995 | E8: Pre-Production | F8: Pre-Production | G8: 31515 | H8: 31514 | I8: 63029 | J8: =VLOOKUP(B8,'Mar 26'!B:G,6,FALSE) -> 31515 | K8: 0 | L8: =G8-J8 -> 0 | M8: =L8-K8 -> 0
A9: All New Glass:Chanel UTC | B9: 83846 | C9: WA-C | D9: 45880 | E9: 46076 | F9: Cutting | G9: =108522.5+77742 -> 186264.5 | H9: 108521.5 | I9: 217044 | J9: =VLOOKUP(B9,'Mar 26'!B:G,6,FALSE) -> 108522.5 | K9: 0 | L9: =G9-J9 -> 77742 | M9: =L9-K9 -> 77742
A10: Alli Construction:Chaparral Janiga Residence | B10: 89424 | C10: CA-R | D10: 46090 | E10: Pre-Production | F10: Pre-Production | G10: 16906.51 | H10: 16906.5 | I10: 33813.01 | J10: =VLOOKUP(B10,'Mar 26'!B:G,6,FALSE) -> 16906.51 | K10: 0 | L10: =G10-J10 -> 0 | M10: =L10-K10 -> 0
A11: American Glass & Mirror Company:1000 Nevillewood Drive | B11: 87836 | C11: VA-C | D11: 46098 | E11: Pre-Production | F11: Pre-Production | G11: 18709 | H11: 18709 | I11: 37418 | J11: =VLOOKUP(B11,'Mar 26'!B:G,6,FALSE) -> 18709 | K11: 0 | L11: =G11-J11 -> 0 | M11: =L11-K11 -> 0
A12: American Products Inc (API):LuLulemon Boston Panel | B12: 89707 | C12: FL-C | D12: 46107 | E12: Pre-Production | F12: Cancelled 4/21 | G12: 0 | J12: =VLOOKUP(B12,'Mar 26'!B:G,6,FALSE) -> 3227 | K12: =J12-G12 -> 3227 | L12: Invoiced This Month | M12: =0-K12 -> -3227
A13: Angie Nyborg:Nyborg Residence | B13: 89450 | C13: NV-R | D13: 46097 | E13: Pre-Production | F13: Pre-Production | G13: 29728 | H13: 31453 | I13: 61181 | J13: =VLOOKUP(B13,'Mar 26'!B:G,6,FALSE) -> 29728 | K13: 0 | L13: =G13-J13 -> 0 | M13: =L13-K13 -> 0
A14: Aragon Construction, Inc.:Penta (1) Interior | B14: 84044 | C14: CA-C | D14: 45811 | E14: 46002 | F14: 46129 | G14: 0 | J14: =VLOOKUP(B14,'Mar 26'!B:G,6,FALSE) -> 93528 | K14: =J14-G14 -> 93528 | L14: Invoiced This Month | M14: =-K14 -> -93528
A15: Aragon Construction, Inc.:Penta (2) Exterior | B15: 84046 | C15: CA-C | D15: 45811 | E15: 46002 | F15: 46129 | G15: 0 | J15: =VLOOKUP(B15,'Mar 26'!B:G,6,FALSE) -> 97035 | K15: =J15-G15 -> 97035 | L15: Invoiced This Month | M15: =-K15 -> -97035
A16: Aragon Construction, Inc.:Puente Hills | B16: 82690 | C16: CA-C | D16: 45978 | E16: 46083 | F16: Assembly | G16: 13744 | H16: 12649 | I16: 26393 | J16: =VLOOKUP(B16,'Mar 26'!B:G,6,FALSE) -> 13744 | K16: 0 | L16: =G16-J16 -> 0 | M16: =L16-K16 -> 0
A17: Aune Brothers Construction:2460 Cajon Lane | B17: 86022 | C17: AZ-R | D17: 46091 | E17: 46099 | F17: 46122 | G17: 0 | J17: =VLOOKUP(B17,'Mar 26'!B:G,6,FALSE) -> 4247 | K17: =J17-G17 -> 4247 | L17: Invoiced This Month | M17: =-K17 -> -4247
A18: Aune Brothers Construction:Lake Havasu Multi Slide | B18: 90057 | C18: AZ-R | D18: 46128 | E18: Pre-Production | F18: Pre-Production | G18: 9211 | H18: =I18-G18 -> 9211.77 | I18: 18422.77 | J18: 0 | K18: =IF(G18=0,J18-G18,0) -> 0 | L18: =G18-J18 -> 9211 | M18: =L18-K18 -> 9211
A19: Barbara Bellio:Bellio Residence | B19: 87402 | C19: NV-R | D19: 45939 | E19: 46106 | F19: 46141 | G19: 0 | J19: =VLOOKUP(B19,'Mar 26'!B:G,6,FALSE) -> 20000 | K19: =J19-G19 -> 20000 | L19: Invoiced This Month | M19: =-K19 -> -20000
A20: Best Contracting LLC:UCSB San Benito Housing | B20: 87022 | C20: CA-C | D20: 45981 | E20: Pre-Production | F20: Pre-Production | G20: 60823 | H20: 60822 | I20: 121645 | J20: =VLOOKUP(B20,'Mar 26'!B:G,6,FALSE) -> 60823 | K20: 0 | L20: =G20-J20 -> 0 | M20: =L20-K20 -> 0
A21: Bill Jaeger:Jaeger Sliders | B21: 90185 | C21: NV-R | D21: 46140 | E21: Pre-Production | F21: Pre-Production | G21: 7191 | H21: =I21-G21 -> 7301.27 | I21: 14492.27 | K21: =IF(G21=0,J21-G21,0) -> 0 | L21: =G21-J21 -> 7191 | M21: =L21-K21 -> 7191
A22: BMG Door & Glass:Rowley | B22: 88961 | C22: AZ-R | D22: 46062 | E22: 46091 | F22: 46128 | G22: 0 | J22: =VLOOKUP(B22,'Mar 26'!B:G,6,FALSE) -> 22865 | K22: =J22-G22 -> 22865 | L22: Invoiced This Month | M22: =-K22 -> -22865
A23: BMG Door & Glass:Unell Door | B23: 89636 | C23: AZ-R | D23: 46122 | E23: Pre-Production | F23: Pre-Production | G23: 4764 | H23: =I23-G23 -> 4764 | I23: 9528 | J23: 0 | K23: 0 | L23: =G23-J23 -> 4764 | M23: =L23-K23 -> 4764
A24: Brad Lager:Palmer | B24: 87591 | C24: MO-R | D24: 46058 | E24: Pre-Production | F24: Pre-Production | G24: 25317 | H24: 25316 | I24: 50633 | J24: =VLOOKUP(B24,'Mar 26'!B:G,6,FALSE) -> 25317 | K24: 0 | L24: =G24-J24 -> 0 | M24: =L24-K24 -> 0
A25: Brett Hill Construction, Inc:4895 Kalanianaole | B25: 88674 | C25: HI-R | D25: 46055 | E25: Pre-Production | F25: Pre-Production | G25: 238760 | H25: 238759 | I25: 477519 | J25: =VLOOKUP(B25,'Mar 26'!B:G,6,FALSE) -> 238760 | K25: 0 | L25: =G25-J25 -> 0 | M25: =L25-K25 -> 0
A26: Builders Direct Supply:4545 North-Studio | B26: 85791 | C26: CA-R | D26: 45959 | E26: Pre-Production | F26: Pre-Production | G26: 8977.7 | H26: 80799.3 | I26: 89777 | J26: =VLOOKUP(B26,'Mar 26'!B:G,6,FALSE) -> 8977.7 | K26: 0 | L26: =G26-J26 -> 0 | M26: =L26-K26 -> 0
A27: Builders Direct Supply:Christian Rooney | B27: 89792 | C27: CA-R | D27: 46140 | E27: Pre-Production | F27: Pre-Production | G27: 34278 | H27: =I27-G27 -> 34278 | I27: 68556 | K27: =IF(G27=0,J27-G27,0) -> 0 | L27: =G27-J27 -> 34278 | M27: =L27-K27 -> 34278
A28: Builders Direct Supply:Marriott | B28: 88115 | C28: CA-C | D28: 46059 | E28: 46084 | F28: 46129 | G28: 0 | J28: =VLOOKUP(B28,'Mar 26'!B:G,6,FALSE) -> 62150.5 | K28: =J28-G28 -> 62150.5 | L28: Invoiced This Month | M28: =-K28 -> -62150.5
A29: Builders Direct Supply:North 4545 | B29: 83690 | C29: CA-R | D29: 45959 | E29: Pre-Production | F29: Pre-Production | G29: 41681.4 | H29: 375132.6 | I29: 416814 | J29: =VLOOKUP(B29,'Mar 26'!B:G,6,FALSE) -> 41681.4 | K29: 0 | L29: =G29-J29 -> 0 | M29: =L29-K29 -> 0
A30: Builders Direct Supply:Snell and Wilmer | B30: 86318 | C30: CA-C | D30: 46030 | E30: Pre-Production | F30: Pre-Production | G30: =26483.5+4914.5 -> 31398 | H30: 26483.5 | I30: 52967 | J30: =VLOOKUP(B30,'Mar 26'!B:G,6,FALSE) -> 26483.5 | K30: 0 | L30: =G30-J30 -> 4914.5 | M30: =L30-K30 -> 4914.5
A31: Builders FirstSource/Dixieline Lumber & Home Center:Bhill Orange County | B31: 89482 | C31: CA-R | D31: 46111 | E31: Pre-Production | F31: Pre-Production | G31: 4138 | H31: 4138 | I31: 8276 | J31: =VLOOKUP(B31,'Mar 26'!B:G,6,FALSE) -> 4138 | K31: 0 | L31: =G31-J31 -> 0 | M31: =L31-K31 -> 0
A32: Builders FirstSource/Dixieline Lumber & Home Center:Dixieline Lumber & Home Center:Rick Moore | B32: 89242 | C32: CA-C | D32: 46083 | E32: 46111 | F32: 46135 | G32: 0 | J32: =VLOOKUP(B32,'Mar 26'!B:G,6,FALSE) -> 8432 | K32: =J32-G32 -> 8432 | L32: Invoiced This Month | M32: =-K32 -> -8432
A33: Buzick Construction, Inc.:Big Blue Bar | B33: 90093 | C33: KY-C | D33: 46127 | E33: Pre-Production | F33: Pre-Production | G33: 20789 | H33: =I33-G33 -> 20789.52 | I33: 41578.52 | J33: 0 | K33: 0 | L33: =G33-J33 -> 20789 | M33: =L33-K33 -> 20789
A34: C Thru Glass:Mt. Charleston Lodge | B34: 89607 | C34: NV-C | D34: 46126 | E34: Pre-Production | F34: Pre-Production | G34: 19335 | H34: =I34-G34 -> 19335 | I34: 38670 | J34: 0 | K34: 0 | L34: =G34-J34 -> 19335 | M34: =L34-K34 -> 19335
A35: CAC Aluminum & Glass Inc.:355 Deerfield Sliding Doors | B35: 89649 | C35: IL-C | D35: 46101 | E35: Pre-Production | F35: Pre-Production | G35: 17176 | H35: 17175 | I35: 34351 | J35: =VLOOKUP(B35,'Mar 26'!B:G,6,FALSE) -> 17176 | K35: 0 | L35: =G35-J35 -> 0 | M35: =L35-K35 -> 0
A36: Callender's House of Glass:750 Picacho Ln | B36: 90005 | C36: CA-R | D36: 46128 | E36: Pre-Production | F36: Pre-Production | G36: 9786 | H36: =I36-G36 -> 9785.44 | I36: 19571.44 | J36: 0 | K36: =IF(G36=0,J36-G36,0) -> 0 | L36: =G36-J36 -> 9786 | M36: =L36-K36 -> 9786
A37: Capitol Glass & Aluminum Co.:Cypress Village | B37: 88240 | C37: FL-C | D37: 46062 | E37: 46090 | F37: 46122 | G37: 0 | J37: =VLOOKUP(B37,'Mar 26'!B:G,6,FALSE) -> 16435.5 | K37: =J37-G37 -> 16435.5 | L37: Invoiced This Month | M37: =-K37 -> -16435.5
A38: Capitol Glass Company:Sunnydale Block 7 | B38: 88227 | C38: CA-C | D38: 46020 | E38: Pre-Production | F38: Pre-Production | G38: 32005 | H38: 32005 | I38: 64010 | J38: =VLOOKUP(B38,'Mar 26'!B:G,6,FALSE) -> 32005 | K38: 0 | L38: =G38-J38 -> 0 | M38: =L38-K38 -> 0
A39: Capitol Glass Company:The Eliza | B39: 84966 | C39: CA-C | D39: 46099 | E39: Pre-Production | F39: Pre-Production | G39: 39804 | H39: 39803 | I39: 79607 | J39: =VLOOKUP(B39,'Mar 26'!B:G,6,FALSE) -> 39804 | K39: 0 | L39: =G39-J39 -> 0 | M39: =L39-K39 -> 0
A40: Catalyst Acoustics Group | B40: Unknown | D40: 44712 | E40: Pre-Production | F40: Pre-Production | G40: 4108 | H40: 0 | I40: 4108 | J40: =VLOOKUP(B40,'Mar 26'!B:G,6,FALSE) -> 4108 | K40: 0 | L40: =G40-J40 -> 0 | M40: =L40-K40 -> 0
...

Sheet May 26
A1: Customer | B1: Q Number | C1: Region | D1: Payment Date | E1: Production Start Day | F1: Stage | G1: DEPOSIT | H1: FINAL | I1: TOTAL | J1: BOM Dep | K1: Dep to Rev | L1: New Dep this Month
A2: 1st Choice Glass:MUSC - Clemson | B2: 88562 | C2: NC-C | D2: 46091 | E2: Pre-Production | F2: Pre-Production | G2: 51110.14 | H2: 0 | I2: 51110.14 | J2: =IFERROR(VLOOKUP(B2,'Apr 26'!B:G,6,FALSE),0) -> 51110.14 | K2: 0 | L2: =G2-J2 -> 0
A3: A&A Window Products Inc:45 Littles Road | B3: 88556 | C3: MA-R | D3: 46086 | E3: Pre-Production | F3: Pre-Production | G3: 11662 | H3: 11662 | I3: 23324 | J3: =IFERROR(VLOOKUP(B3,'Apr 26'!B:G,6,FALSE),0) -> 11662 | K3: 0 | L3: =G3-J3 -> 0
A4: Advanced Windows:1990 K Street | B4: 87616 | C4: MD-C | D4: 46069 | E4: Pre-Production | F4: Pre-Production | G4: 35586 | H4: 9375 | I4: 44961 | J4: =IFERROR(VLOOKUP(B4,'Apr 26'!B:G,6,FALSE),0) -> 35586 | K4: 0 | L4: =G4-J4 -> 0
A5: Advanced Windows:Golden Hill | B5: 84541 | C5: MD-C | D5: 45943 | E5: 46083 | F5: 46153 | G5: 0 | J5: =IFERROR(VLOOKUP(B5,'Apr 26'!B:G,6,FALSE),0) -> 10262 | K5: =J5-G5 -> 10262 | L5: Invoiced This Month
A6: AFR Construction:Boe Dekker | B6: 87676 | C6: NV-R | D6: 46125 | E6: Pre-Production | F6: Pre-Production | G6: 2400.25 | H6: =I6-G6 -> 2449.75 | I6: 4850 | J6: =IFERROR(VLOOKUP(B6,'Apr 26'!B:G,6,FALSE),0) -> 2400.25 | K6: 0 | L6: =G6-J6 -> 0
A7: Ajay Glass & Mirror Co., Inc.:Billitier | B7: 89718 | C7: NY-R | D7: 46105 | E7: 46119 | F7: 46153 | G7: 0 | J7: =IFERROR(VLOOKUP(B7,'Apr 26'!B:G,6,FALSE),0) -> 9796.19 | K7: =J7-G7 -> 9796.19 | L7: Invoiced This Month
A8: Akis Doganis:Doganis Residence | B8: 87185 | C8: NV-R | D8: 45995 | E8: Pre-Production | F8: Pre-Production | G8: 31515 | H8: 31514 | I8: 63029 | J8: =IFERROR(VLOOKUP(B8,'Apr 26'!B:G,6,FALSE),0) -> 31515 | K8: 0 | L8: =G8-J8 -> 0
A9: All New Glass:Chanel UTC | B9: 83846 | C9: WA-C | D9: 45880 | E9: 46076 | F9: 46163 | G9: 0 | J9: =IFERROR(VLOOKUP(B9,'Apr 26'!B:G,6,FALSE),0) -> 186264.5 | K9: =J9-G9 -> 186264.5 | L9: Invoiced This Month
A10: Alli Construction:Chaparral Janiga Residence | B10: 89424 | C10: CA-R | D10: 46090 | E10: 46141 | F10: Pull Material | G10: 16906.51 | H10: 16906.5 | I10: 33813.01 | J10: =IFERROR(VLOOKUP(B10,'Apr 26'!B:G,6,FALSE),0) -> 16906.51 | K10: 0 | L10: =G10-J10 -> 0
A11: American Glass & Mirror Company:1000 Nevillewood Drive | B11: 87836 | C11: VA-C | D11: 46098 | E11: Pre-Production | F11: Pre-Production | G11: 18709 | H11: 18709 | I11: 37418 | J11: =IFERROR(VLOOKUP(B11,'Apr 26'!B:G,6,FALSE),0) -> 18709 | K11: 0 | L11: =G11-J11 -> 0
A12: Angie Nyborg:Nyborg Residence | B12: 89450 | C12: NV-R | D12: 46097 | E12: 46122 | F12: 46171 | G12: 0 | J12: =IFERROR(VLOOKUP(B12,'Apr 26'!B:G,6,FALSE),0) -> 29728 | K12: =IF(G12=0,J12-G12,0) -> 29728 | L12: Invoiced This Month
A13: Aragon Construction, Inc.:Puente Hills | B13: 82690 | C13: CA-C | D13: 45978 | E13: 46083 | F13: 46171 | G13: 0 | J13: =IFERROR(VLOOKUP(B13,'Apr 26'!B:G,6,FALSE),0) -> 13744 | K13: =IF(G13=0,J13-G13,0) -> 13744 | L13: Invoiced This Month
A14: Architectural Glass & Design:9825 Stonecrest | B14: 88159 | C14: CA-C | D14: 46148 | E14: Pre-Production | F14: Pre-Production | G14: 8819 | H14: =I14-G14 -> 8818 | I14: 17637 | J14: =IFERROR(VLOOKUP(B14,'Apr 26'!B:G,6,FALSE),0) -> 0 | K14: 0 | L14: =G14-J14 -> 8819
A15: Aune Brothers Construction:Lake Havasu Multi Slide | B15: 90057 | C15: AZ-R | D15: 46128 | E15: Pre-Production | F15: Pre-Production | G15: 9211 | H15: =I15-G15 -> 9211.77 | I15: 18422.77 | J15: =IFERROR(VLOOKUP(B15,'Apr 26'!B:G,6,FALSE),0) -> 9211 | K15: =IF(G15=0,J15-G15,0) -> 0 | L15: =G15-J15 -> 0
A16: Best Contracting LLC:UCSB San Benito Housing | B16: 87022 | C16: CA-C | D16: 45981 | E16: Pre-Production | F16: Pre-Production | G16: 60823 | H16: 60822 | I16: 121645 | J16: =IFERROR(VLOOKUP(B16,'Apr 26'!B:G,6,FALSE),0) -> 60823 | K16: 0 | L16: =G16-J16 -> 0
A17: Bill Jaeger:Jaeger Sliders | B17: 90185 | C17: NV-R | D17: 46140 | E17: Pre-Production | F17: Pre-Production | G17: 7191 | H17: =I17-G17 -> 7301.27 | I17: 14492.27 | J17: =IFERROR(VLOOKUP(B17,'Apr 26'!B:G,6,FALSE),0) -> 7191 | K17: =IF(G17=0,J17-G17,0) -> 0 | L17: =G17-J17 -> 0
A18: BMG Door & Glass:Unell Door | B18: 89636 | C18: AZ-R | D18: 46122 | E18: 46127 | F18: 46170 | G18: 0 | J18: =IFERROR(VLOOKUP(B18,'Apr 26'!B:G,6,FALSE),0) -> 4764 | K18: =IF(G18=0,J18-G18,0) -> 4764 | L18: Invoiced This Month
A19: Boulder Ridge Sash & Door:129 Tahoe Tavern | B19: 89731 | C19: CA-R | D19: 46147 | E19: Pre-Production | F19: Pre-Production | G19: 13338.01 | H19: =I19-G19 -> 13336.99 | I19: 26675 | J19: =IFERROR(VLOOKUP(B19,'Apr 26'!B:G,6,FALSE),0) -> 0 | K19: 0 | L19: =G19-J19 -> 13338.01
A20: Boyett Construction Inc:Ian | B20: 90450 | C20: CA-R | D20: 46146 | E20: Pre-Production | F20: Pre-Production | G20: 7699 | H20: =I20-G20 -> 7699.29 | I20: 15398.29 | J20: =IFERROR(VLOOKUP(B20,'Apr 26'!B:G,6,FALSE),0) -> 0 | K20: 0 | L20: =G20-J20 -> 7699
A21: Brad Lager:Palmer | B21: 87591 | C21: MO-R | D21: 46058 | E21: 46125 | F21: Pull Material | G21: 25317 | H21: 25316 | I21: 50633 | J21: =IFERROR(VLOOKUP(B21,'Apr 26'!B:G,6,FALSE),0) -> 25317 | K21: 0 | L21: =G21-J21 -> 0
A22: Brett Hill Construction, Inc:4895 Kalanianaole | B22: 88674 | C22: HI-R | D22: 46055 | E22: 46132 | F22: Pull Material | G22: 238760 | H22: 238759 | I22: 477519 | J22: =IFERROR(VLOOKUP(B22,'Apr 26'!B:G,6,FALSE),0) -> 238760 | K22: 0 | L22: =G22-J22 -> 0
A23: Builders Direct Supply:4545 North-Studio | B23: 85791 | C23: CA-R | D23: 45959 | E23: Pre-Production | F23: Pre-Production | G23: 8977.7 | H23: 80799.3 | I23: 89777 | J23: =IFERROR(VLOOKUP(B23,'Apr 26'!B:G,6,FALSE),0) -> 8977.7 | K23: 0 | L23: =G23-J23 -> 0
A24: Builders Direct Supply:Christian Rooney | B24: 89792 | C24: CA-R | D24: 46140 | E24: Pre-Production | F24: Pre-Production | G24: 34278 | H24: =I24-G24 -> 34278 | I24: 68556 | J24: =IFERROR(VLOOKUP(B24,'Apr 26'!B:G,6,FALSE),0) -> 34278 | K24: =IF(G24=0,J24-G24,0) -> 0 | L24: =G24-J24 -> 0
A25: Builders Direct Supply:Keel Residence | B25: 90329 | C25: CA-R | D25: 05/14/2026 | E25: Pre-Production | F25: Pre-Production | G25: 8966.25 | H25: =I25-G25 -> 8966.3 | I25: 17932.55 | J25: =IFERROR(VLOOKUP(B25,'Apr 26'!B:G,6,FALSE),0) -> 0 | K25: 0 | L25: =G25-J25 -> 8966.25
A26: Builders Direct Supply:North 4545 | B26: 83690 | C26: CA-R | D26: 45959 | E26: Pre-Production | F26: Pre-Production | G26: 41681.4 | H26: 375132.6 | I26: 416814 | J26: =IFERROR(VLOOKUP(B26,'Apr 26'!B:G,6,FALSE),0) -> 41681.4 | K26: 0 | L26: =G26-J26 -> 0
A27: Builders Direct Supply:Snell and Wilmer | B27: 86318 | C27: CA-C | D27: 46030 | E27: 46140 | F27: Pull Material | G27: =26483.5+4914.5 -> 31398 | H27: 26483.5 | I27: 52967 | J27: =IFERROR(VLOOKUP(B27,'Apr 26'!B:G,6,FALSE),0) -> 31398 | K27: 0 | L27: =G27-J27 -> 0
A28: Builders FirstSource/Dixieline Lumber & Home Center:1416 Stone Canyon Rd | B28: 89873 | C28: CA-R | D28: 46168 | E28: Pre-Production | F28: Pre-Production | G28: 165000 | H28: =I28-G28 -> 165000 | I28: 330000 | L28: =G28-J28 -> 165000
A29: Builders FirstSource/Dixieline Lumber & Home Center:Bhill Orange County | B29: 89482 | C29: CA-R | D29: 46111 | E29: 46119 | F29: 46143 | G29: 0 | J29: =IFERROR(VLOOKUP(B29,'Apr 26'!B:G,6,FALSE),0) -> 4138 | K29: =J29-G29 -> 4138 | L29: Invoiced This Month
A30: Builders FirstSource/Dixieline Lumber & Home Center:Kyle Newport | B30: 90207 | C30: CA-R | D30: 46168 | E30: Pre-Production | F30: Pre-Production | G30: 4969 | H30: =I30-G30 -> 4970 | I30: 9939 | L30: =G30-J30 -> 4969
A31: Buzick Construction, Inc.:Big Blue Bar | B31: 90093 | C31: KY-C | D31: 46127 | E31: Pre-Production | F31: Pre-Production | G31: 20789 | H31: =I31-G31 -> 20789.52 | I31: 41578.52 | J31: =IFERROR(VLOOKUP(B31,'Apr 26'!B:G,6,FALSE),0) -> 20789 | K31: 0 | L31: =G31-J31 -> 0
A32: C Thru Glass:Mt. Charleston Lodge | B32: 89607 | C32: NV-C | D32: 46126 | E32: Pre-Production | F32: Pre-Production | G32: 19335 | H32: =I32-G32 -> 19335 | I32: 38670 | J32: =IFERROR(VLOOKUP(B32,'Apr 26'!B:G,6,FALSE),0) -> 19335 | K32: 0 | L32: =G32-J32 -> 0
A33: CAC Aluminum & Glass Inc.:355 Deerfield Sliding Doors | B33: 89649 | C33: IL-C | D33: 46101 | E33: 46126 | F33: Pull Material | G33: 17176 | H33: 17175 | I33: 34351 | J33: =IFERROR(VLOOKUP(B33,'Apr 26'!B:G,6,FALSE),0) -> 17176 | K33: 0 | L33: =G33-J33 -> 0
A34: Callender's House of Glass:750 Picacho Ln | B34: 90005 | C34: CA-R | D34: 46128 | E34: Pre-Production | F34: Pre-Production | G34: 9786 | H34: =I34-G34 -> 9785.44 | I34: 19571.44 | J34: =IFERROR(VLOOKUP(B34,'Apr 26'!B:G,6,FALSE),0) -> 9786 | K34: =IF(G34=0,J34-G34,0) -> 0 | L34: =G34-J34 -> 0
A35: Capitol Glass Company:Sunnydale Block 7 | B35: 88227 | C35: CA-C | D35: 46020 | E35: 46133 | F35: Pull Material | G35: 32005 | H35: 32005 | I35: 64010 | J35: =IFERROR(VLOOKUP(B35,'Apr 26'!B:G,6,FALSE),0) -> 32005 | K35: 0 | L35: =G35-J35 -> 0
A36: Capitol Glass Company:The Eliza | B36: 84966 | C36: CA-C | D36: 46099 | E36: Pre-Production | F36: Pre-Production | G36: 39804 | H36: 39803 | I36: 79607 | J36: =IFERROR(VLOOKUP(B36,'Apr 26'!B:G,6,FALSE),0) -> 39804 | K36: 0 | L36: =G36-J36 -> 0
A37: Catalyst Acoustics Group | B37: Unknown | D37: 44712 | E37: Pre-Production | F37: Pre-Production | G37: 4108 | H37: 0 | I37: 4108 | J37: =IFERROR(VLOOKUP(B37,'Apr 26'!B:G,6,FALSE),0) -> 4108 | K37: 0 | L37: =G37-J37 -> 0
A38: Charles Chou:Chou Folding Window | B38: 90088 | C38: NV-R | D38: 46118 | E38: 46134 | F38: 46155 | G38: 0 | J38: =IFERROR(VLOOKUP(B38,'Apr 26'!B:G,6,FALSE),0) -> 2638 | K38: =J38-G38 -> 2638 | L38: Invoiced This Month
A39: Charlotte Rosiak:1805 Villa De Conde Way Entry | B39: 90923 | C39: NV-R | D39: 46160 | E39: Pre-Production | F39: Pre-Production | G39: 7275.85 | H39: =I39-G39 -> 7275.84 | I39: 14551.69 | L39: =G39-J39 -> 7275.85
A40: Chase Kloehn:Kloehn Remodel | B40: 88513 | C40: NV-R | D40: 46085 | E40: Pre-Production | F40: Pre-Production | G40: 11224 | H40: 13423 | I40: 24647 | J40: =IFERROR(VLOOKUP(B40,'Apr 26'!B:G,6,FALSE),0) -> 11224 | K40: 0 | L40: =G40-J40 -> 0
...

Sheet Jun 26
A1: Customer | B1: Q Number | C1: Region | D1: Payment Date | E1: Production Start Day | F1: Stage | G1: DEPOSIT | H1: FINAL | I1: TOTAL | J1: BOM Dep | K1: Dep to Rev | L1: New Dep this Month
A2: 1st Choice Glass:MUSC - Clemson | B2: 88562 | C2: NC-C | D2: 46091 | E2: Pre-Production | F2: Pre-Production | G2: 51110.14 | H2: 0 | I2: 51110.14 | J2: =IFERROR(VLOOKUP(B2,'May 26'!B:G,6,FALSE),0) -> 51110.14 | K2: 0 | L2: =G2-J2 -> 0 | N2: =VLOOKUP(B2,[3]invoicing!$C:$AI,33,FALSE)
A3: A&A Window Products Inc:45 Littles Road | B3: 88556 | C3: MA-R | D3: 46086 | E3: 46150 | F3: 46202 | G3: 0 | J3: =IFERROR(VLOOKUP(B3,'May 26'!B:G,6,FALSE),0) -> 11662 | K3: =J3-G3 -> 11662 | L3: Invoiced This Month
A4: AAC Glass Inc.:PUSD Folding Door | B4: 88164 | C4: CA-C | D4: 46195 | E4: Pre-Production | F4: Pre-Production | G4: 22283 | H4: =I4-G4 -> 22282 | I4: 44565 | J4: =IFERROR(VLOOKUP(B4,'May 26'!B:G,6,FALSE),0) -> 0 | K4: 0 | L4: =G4-J4 -> 22283
A5: Advanced Windows:1990 K Street | B5: 87616 | C5: MD-C | D5: 46069 | E5: Pre-Production | F5: Pre-Production | G5: 35586 | H5: 9375 | I5: 44961 | J5: =IFERROR(VLOOKUP(B5,'May 26'!B:G,6,FALSE),0) -> 35586 | K5: 0 | L5: =G5-J5 -> 0
A6: AFR Construction:Boe Dekker | B6: 87676 | C6: NV-R | D6: 46125 | E6: 46153 | F6: 46185 | G6: 0 | J6: =IFERROR(VLOOKUP(B6,'May 26'!B:G,6,FALSE),0) -> 2400.25 | K6: =J6-G6 -> 2400.25 | L6: Invoiced This Month | N6: =VLOOKUP(B6,[3]invoicing!$C:$AI,33,FALSE)
A7: Akis Doganis:Doganis Residence | B7: 87185 | C7: NV-R | D7: 45995 | E7: Pre-Production | F7: Pre-Production | G7: 31515 | H7: 31514 | I7: 63029 | J7: =IFERROR(VLOOKUP(B7,'May 26'!B:G,6,FALSE),0) -> 31515 | K7: 0 | L7: =G7-J7 -> 0 | N7: =VLOOKUP(B7,[3]invoicing!$C:$AI,33,FALSE)
A8: Alli Construction:Chaparral Janiga Residence | B8: 89424 | C8: CA-R | D8: 46090 | E8: 46141 | F8: 46185 | G8: 0 | J8: =IFERROR(VLOOKUP(B8,'May 26'!B:G,6,FALSE),0) -> 16906.51 | K8: =J8-G8 -> 16906.51 | L8: Invoiced This Month | N8: =VLOOKUP(B8,[3]invoicing!$C:$AI,33,FALSE)
A9: American Glass & Mirror Company:1000 Nevillewood Drive | B9: 87836 | C9: VA-C | D9: 46098 | E9: 46191 | F9: Powder Coat | G9: 18709 | H9: 18709 | I9: 37418 | J9: =IFERROR(VLOOKUP(B9,'May 26'!B:G,6,FALSE),0) -> 18709 | K9: 0 | L9: =G9-J9 -> 0 | N9: =VLOOKUP(B9,[3]invoicing!$C:$AI,33,FALSE)
