Workbook

Sheet Summary
A1: Signed Sales Order / Pending Shop Drawings - deal-by-deal check
A2: Source: monday.com Opportunities board, group "Signed Sales Order/Pending Shop Drawings", pulled 10/2/26. Cross-checked to the Project Managers board and the 2026 customer deposit tabs.
A4: Classification | B4: # Deals | C4: Project Total | D4: Panda #
A5: Valid backlog | B5: =COUNTIF(Deals!$N:$N,A5) | C5: =SUMIF(Deals!$N:$N,A5,Deals!$H:$H) | D5: =SUMIF(Deals!$N:$N,A5,Deals!$I:$I)
A6: Check - 2025 win, no deposit, not on PM board | B6: =COUNTIF(Deals!$N:$N,A6) | C6: =SUMIF(Deals!$N:$N,A6,Deals!$H:$H) | D6: =SUMIF(Deals!$N:$N,A6,Deals!$I:$I)
A7: Remove - already produced / shipped | B7: =COUNTIF(Deals!$N:$N,A7) | C7: =SUMIF(Deals!$N:$N,A7,Deals!$H:$H) | D7: =SUMIF(Deals!$N:$N,A7,Deals!$I:$I)
A8: Remove - canceled on PM board | B8: =COUNTIF(Deals!$N:$N,A8) | C8: =SUMIF(Deals!$N:$N,A8,Deals!$H:$H) | D8: =SUMIF(Deals!$N:$N,A8,Deals!$I:$I)
A9: Won in October (after 10/1 snapshot) | B9: =COUNTIF(Deals!$N:$N,A9) | C9: =SUMIF(Deals!$N:$N,A9,Deals!$H:$H) | D9: =SUMIF(Deals!$N:$N,A9,Deals!$I:$I)
A10: Total in group today | B10: =SUM(B5:B9) | C10: =SUM(C5:C9) | D10: =SUM(D5:D9)
A12: As shown on dashboard (10/1 snapshot): all deals won before 10/1 | B12: =B10-B9 | C12: =C10-C9 | D12: =D10-D9
A13: Dashboard figure (hardcoded) | B13: 140 | C13: 9700000 | E13: Typed into the dashboard page; not recalculated
A14: Corrected backlog: valid + to check | B14: =B5+B6 | C14: =C5+C6 | D14: =D5+D6
A15: Corrected backlog: valid only | B15: =B5 | C15: =C5 | D15: =D5
A17: Notes
A18: 14 deals have no Project Total entered, so their value is missing from every dollar figure.
A19: "Deposit on 2026 tab" only checks the Jan-Sep 2026 customer deposit tabs; a deposit collected in 2025 will show No.
A20: Remove rows: the PM board already shows these jobs shipped, closed out or canceled, so they are not waiting on shop drawings. Move them out of this group in monday.
A21: Check rows: won in 2025, no 2026 deposit and no PM board job. Probably dead or never started; confirm with the RSM.

Sheet Deals
A1: RSM | B1: Deal | C1: Project / Company | D1: Q# | E1: Stage | F1: Deal Won | G1: Won Date | H1: Project Total | I1: Panda # | J1: Shop Drawings? | K1: Drawings Signed? | L1: PM Board Group | M1: Deposit on 2026 tab | N1: Classification | O1: Opp Last Updated | P1: monday link
A2: Bill Davenport | B2: Daniel Moran | C2: Moran Residence | D2: 90891 / 2092 | E2: Signed SO/Pending Drawings | F2: Yes | G2: 46232 | H2: 9757 | I2: 5217 | J2: No | K2: No | L2: Not on PM board | M2: No | N2: Valid backlog | O2: 46240 | P2: https://panda-windows-and-doors.monday.com/boards/7469134152/pulses/11989151816
A3: Bill Davenport | B3: Kenneth VanBuskirk | C3: Detroit Pistons Locker Room | D3: 92529 | E3: Signed SO/Pending Drawings | F3: Yes | G3: 46275 | J3: No | K3: No | L3: Not on PM board | M3: No | N3: Valid backlog | O3: 46290 | P3: https://panda-windows-and-doors.monday.com/boards/7469134152/pulses/12970532244
A4: Derrick McCall | B4: J Shuman Door Installation | C4: Hospitality Building | D4: 86579 | E4: Signed SO/Pending Drawings | F4: Yes | G4: 46188 | H4: 153173 | I4: 135977.87 | J4: Yes | K4: No | L4: Sent to Engineering | M4: Yes | N4: Valid backlog | O4: 46212 | P4: https://panda-windows-and-doors.monday.com/boards/7469134152/pulses/9645512025
A5: Derrick McCall | B5: Best Contracting | C5: UCSB San Benito Housing | D5: 87022 | E5: Signed SO/Pending Drawings | F5: Yes | G5: 45965 | H5: 121645 | I5: 107495.35 | J5: Yes | K5: No | L5: Sent to Engineering | M5: Yes | N5: Valid backlog | O5: 46120 | P5: https://panda-windows-and-doors.monday.com/boards/7469134152/pulses/18346441407
A6: Derrick McCall | B6: Pacific Glazing Contractors | C6: Mission Bay South 4E Phase 2 | D6: 89502 | E6: Proposal Sent to Client | F6: Yes | G6: 46141 | H6: 107644 | I6: 92836.96 | J6: No | K6: No | L6: Pending Deposit in Invoicing | M6: No | N6: Valid backlog | O6: 46141 | P6: https://panda-windows-and-doors.monday.com/boards/7469134152/pulses/11342933243
A7: Derrick McCall | B7: Classic Glass | C7: Hotel Mohi | D7: 88845 | E7: Signed SO/Pending Drawings | F7: Yes | G7: 46101 | H7: 103637 | I7: 90249.35 | J7: Yes | K7: No | L7: Sent to Engineering | M7: Yes | N7: Valid backlog | O7: 46128 | P7: https://panda-windows-and-doors.monday.com/boards/7469134152/pulses/11556409277
A8: Derrick McCall | B8: Progress Glass | C8: Marin Art & Garden Center | D8: 91229 / 2493 | E8: Signed SO/Pending Drawings | F8: Yes | G8: 46281 | H8: 98131.6 | I8: 82015.63 | J8: Yes | K8: No | L8: Not on PM board | M8: Yes | N8: Valid backlog | O8: 46289 | P8: https://panda-windows-and-doors.monday.com/boards/7469134152/pulses/12197775710
A9: Derrick McCall | B9: Capitol Glass Company | C9: The Eliza | D9: 84966 | E9: Signed SO/Pending Drawings | F9: Yes | G9: 45924 | H9: 79208 | I9: 67627.5 | J9: Yes | K9: No | L9: Sent to Engineering | M9: Yes | N9: Valid backlog | O9: 46120 | P9: https://panda-windows-and-doors.monday.com/boards/7469134152/pulses/8917925091
A10: Derrick McCall | B10: Sunset Glazing | C10: 6th & Palm | D10: 84176/4141 | E10: Signed SO/Pending Drawings | F10: Yes | G10: 46245 | H10: 78196.39 | I10: 67355.35 | J10: No | K10: No | L10: Not on PM board | M10: Yes | N10: Valid backlog | O10: 46261 | P10: https://panda-windows-and-doors.monday.com/boards/7469134152/pulses/8627892187
A11: Derrick McCall | B11: Lucky's Glass | C11: Meditation | D11: 86347 / 4593 | E11: Signed SO/Pending Drawings | F11: Yes | G11: 46265 | H11: 65888.32 | I11: 57344.82 | J11: No | K11: No | L11: Not on PM board | M11: No | N11: Valid backlog | O11: 46265 | P11: https://panda-windows-and-doors.monday.com/boards/7469134152/pulses/9534718348
A12: Derrick McCall | B12: Giroux Glass | C12: Sparks Training Facility | D12: 89539 | E12: Signed SO/Pending Drawings | F12: Yes | G12: 46162 | H12: 65212 | I12: 5535.75 | J12: Yes | K12: No | L12: Pending Deposit in Invoicing | M12: Yes | N12: Valid backlog | O12: 46244 | P12: https://panda-windows-and-doors.monday.com/boards/7469134152/pulses/11358077145
A13: Derrick McCall | B13: Walters & Wolf | C13: UCB Bancroft | D13: 87035 | E13: Signed SO/Pending Drawings | F13: Yes | G13: 46175 | H13: 56357 | I13: 48347.41 | J13: Yes | K13: No | L13: Sent to Engineering | M13: Yes | N13: Valid backlog | O13: 46188 | P13: https://panda-windows-and-doors.monday.com/boards/7469134152/pulses/9882140955
A14: Derrick McCall | B14: Elite Glaziers | C14: LA Basketball | D14: 90706 | E14: Signed SO/Pending Drawings | F14: Yes | G14: 46148 | H14: 52480 | I14: 45833.22 | J14: Yes | K14: No | L14: Sent to Engineering | M14: Yes | N14: Valid backlog | O14: 46190 | P14: https://panda-windows-and-doors.monday.com/boards/7469134152/pulses/11801141862
A15: Derrick McCall | B15: Platinum Glass | C15: JP Morgan Chase 7th | D15: 89431 | E15: Signed SO/Pending Drawings | F15: Yes | G15: 46108 | H15: 48064 | I15: 42001.39 | J15: No | K15: No | L15: Pending Deposit in Invoicing | M15: No | N15: Valid backlog | O15: 46120 | P15: https://panda-windows-and-doors.monday.com/boards/7469134152/pulses/11295209764
... A23: Derrick McCall | B23: Maryl Construction | C23: 91108 Hapuna Villa Window | D23: 91108 / 2343 | E23: Signed SO/Pending Drawings | F23: No | G23: 46192 | H23: 10033.21 | I23: 9449.26 | J23: No | K23: No | L23: Pending Deposit in Invoicing | M23: Yes | N23: Valid backlog | O23: 46244 | P23: https://panda-windows-and-doors.monday.com/boards/7469134152/pulses/12321628016
A24: Derrick McCall | B24: JV Glass | C24: Lululemon | E24: Proposal Sent to Client | F24: Yes | G24: 46141 | J24: No | K24: No | L24: Not on PM board | M24: No | N24: Valid backlog | O24: 46141 | P24: https://panda-windows-and-doors.monday.com/boards/7469134152/pulses/11756438433
A25: Derrick McCall | B25: Ian Russell | E25: Signed SO/Pending Drawings | F25: Yes | G25: 46141 | J25: No | K25: No | L25: Not on PM board | M25: No | N25: Valid backlog | O25: 46141 | P25: https://panda-windows-and-doors.monday.com/boards/7469134152/pulses/11775899142
A26: Derrick McCall | B26: Lighthouse Windows, Inc | C26: Warm Springs III - Lot 10 | D26: 91004 / 2209 | E26: Signed SO/Pending Drawings | F26: Yes | G26: 46168 | J26: No | K26: No | L26: Pending Deposit in Invoicing | M26: Yes | N26: Valid backlog | O26: 46168 | P26: https://panda-windows-and-doors.monday.com/boards/7469134152/pulses/12107680812
A27: Derrick McCall | B27: Signature Glass & Windows, Inc. | C27: 3001 ECR | D27: 87059 | E27: Signed SO/Pending Drawings | F27: Yes | G27: 46178 | J27: Yes | K27: No | L27: Sent to Engineering | M27: Yes | N27: Valid backlog | O27: 46202 | P27: https://panda-windows-and-doors.monday.com/boards/7469134152/pulses/12202875911
A28: Efrain Zarate | B28: Dynamic Glass | C28: Antero Resources | D28: 85504 | E28: Signed SO/Pending Drawings | F28: Yes | G28: 46062 | H28: 302136 | I28: 260821.74 | J28: Yes | K28: No | L28: Sent to Engineering | M28: Yes | N28: Valid backlog | O28: 46251 | P28: https://panda-windows-and-doors.monday.com/boards/7469134152/pulses/9322025496
A29: Efrain Zarate | B29: Roseman University of Health Sciences, A Non-Profit Corporation | C29: Roseman University | D29: 88519/2436 | E29: Signed SO/Pending Drawings | F29: Yes | G29: 46275 | H29: 171300.72 | I29: 157156.62 | J29: No | K29: No | L29: Not on PM board | M29: No | N29: Valid backlog | O29: 46275 | P29: https://panda-windows-and-doors.monday.com/boards/7469134152/pulses/10746878829
A30: Efrain Zarate | B30: The Window Store | C30: Black Spur Estate | D30: 85860 | E30: Signed SO/Pending Drawings | F30: Yes | G30: 45817 | H30: 144167 | I30: 125877.52 | J30: Yes | K30: No | L30: Sent to Engineering | M30: Yes | N30: Valid backlog | O30: 46120 | P30: https://panda-windows-and-doors.monday.com/boards/7469134152/pulses/8775248357
A31: Efrain Zarate | B31: Walters & Wolf | C31: HRHC Podium | D31: 87948/4063 | E31: Signed SO/Pending Drawings | F31: Yes | G31: 46245 | H31: 132268.93 | I31: 119456 | J31: No | K31: No | L31: Not on PM board | M31: Yes | N31: Valid backlog | O31: 46281 | P31: https://panda-windows-and-doors.monday.com/boards/7469134152/pulses/12741345459
A32: Efrain Zarate | B32: Sighlines | C32: Blue Martini | D32: 87599 | E32: Signed SO/Pending Drawings | F32: Yes | G32: 45965 | H32: 108261 | I32: 96526.01 | J32: Yes | K32: No | L32: Pending Deposit in Invoicing | M32: Yes | N32: Valid backlog | O32: 46251 | P32: https://panda-windows-and-doors.monday.com/boards/7469134152/pulses/18346471113
A33: Efrain Zarate | B33: Turkel Design | C33: Robbins | D33: 89724/2803 | E33: Signed SO/Pending Drawings | F33: Yes | G33: 46269 | H33: 105977.5 | I33: 83454.5 | J33: Yes | K33: No | L33: Not on PM board | M33: Yes | N33: Valid backlog | O33: 46294 | P33: https://panda-windows-and-doors.monday.com/boards/7469134152/pulses/11884841301
A34: Efrain Zarate | B34: Turkel Design | C34: GAL Residence | D34: 87450 | E34: Signed SO/Pending Drawings | F34: Yes | G34: 46066 | H34: 59540 | I34: 46827.47 | J34: Yes | K34: No | L34: Sent to Engineering | M34: Yes | N34: Valid backlog | O34: 46183 | P34: https://panda-windows-and-doors.monday.com/boards/7469134152/pulses/18025593941
A35: Efrain Zarate | B35: Architectural Windows & Doors | C35: NM Remodel | D35: 91603 | E35: Signed SO/Pending Drawings | F35: Yes | G35: 46248 | H35: 58451 | I35: 47950.47 | J35: Yes | K35: No | L35: Not on PM board | M35: Yes | N35: Valid backlog | O35: 46288 | P35: https://panda-windows-and-doors.monday.com/boards/7469134152/pulses/12426049763
A36: Efrain Zarate | B36: Glass House | C36: Red Arrow | D36: 88672 | E36: Signed SO/Pending Drawings | F36: Yes | G36: 46143 | H36: 47238 | I36: 42892.07 | J36: No | K36: No | L36: Sent to Engineering | M36: No | N36: Valid backlog | O36: 46251 | P36: https://panda-windows-and-doors.monday.com/boards/7469134152/pulses/11076421267
A37: Efrain Zarate | B37: Skyline Glass | C37: Candela's Apartments | D37: 86208 | E37: Signed SO/Pending Drawings | F37: Yes | G37: 46136 | H37: 45573 | I37: 36339.28 | J37: Yes | K37: No | L37: Sent to Engineering | M37: Yes | N37: Valid backlog | O37: 46157 | P37: https://panda-windows-and-doors.monday.com/boards/7469134152/pulses/11842196498
A38: Efrain Zarate | B38: C Thru Glass | C38: Mt. Charleston Lodge | D38: 89607 | E38: Signed SO/Pending Drawings | F38: Yes | G38: 46120 | H38: 38670 | I38: 34479.18 | J38: Yes | K38: No | L38: Sent to Engineering | M38: Yes | N38: Valid backlog | O38: 46251 | P38: https://panda-windows-and-doors.monday.com/boards/7469134152/pulses/11464599738
A39: Efrain Zarate | B39: BMG Door & Glass | C39: Halise Diamond | D39: 89197 | E39: Signed SO/Pending Drawings | F39: No | H39: 38046.13 | I39: 33122.14 | J39: Yes | K39: No | L39: Not on PM board | M39: Yes | N39: Valid backlog | O39: 46251 | P39: https://panda-windows-and-doors.monday.com/boards/7469134152/pulses/11778239085
A40: Efrain Zarate | B40: Ken Caryl Glass Inc | C40: McDonald Audi | D40: 91176/2447 | E40: Signed SO/Pending Drawings | F40: Yes | G40: 46269 | H40: 35384.86 | I40: 29192.58 | J40: Yes | K40: No | L40: Not on PM board | M40: Yes | N40: Valid backlog | O40: 46286 | P40: https://panda-windows-and-doors.monday.com/boards/7469134152/pulses/12181024331
A41: Efrain Zarate | B41: Tridel Construction | C41: Players Canyon - Doors | D41: 84246 | E41: Signed SO/Pending Drawings | F41: Yes | G41: 45978 | H41: 34230 | I41: 30940.12 | J41: Yes | K41: No | L41: Sent to Engineering | M41: Yes | N41: Valid backlog | O41: 46120 | P41: https://panda-windows-and-doors.monday.com/boards/7469134152/pulses/8646895020
A42: Efrain Zarate | B42: 8 G Solutions | C42: Marina Square | D42: 83756/2591 | E42: Signed SO/Pending Drawings | F42: Yes | G42: 46226 | H42: 29958.12 | I42: 23292.77 | J42: Yes | K42: No | L42: Not on PM board | M42: Yes | N42: Valid backlog | O42: 46251 | P42: https://panda-windows-and-doors.monday.com/boards/7469134152/pulses/11885010447
A43: Efrain Zarate | B43: Amber Martinez | C43: Martinez Pivot | D43: 92314/4228 | E43: Signed SO/Pending Drawings | F43: Yes | G43: 46252 | H43: 29037.48 | I43: 25079.7 | J43: No | K43: No | L43: Not on PM board | M43: Yes | N43: Valid backlog | O43: 46255 | P43: https://panda-windows-and-doors.monday.com/boards/7469134152/pulses/12777585608
A44: Efrain Zarate | B44: Mesa Properties | C44: 2435 Legacy Dr | D44: 85687 | E44: Signed SO/Pending Drawings | F44: Yes | G44: 46233 | H44: 26587 | I44: 22382 | J44: Yes | K44: No | L44: Not on PM board | M44: Yes | N44: Valid backlog | O44: 46240 | P44: https://panda-windows-and-doors.monday.com/boards/7469134152/pulses/12582634150
A45: Efrain Zarate | B45: American Eagle Glass | C45: AAA Blue Diamond | D45: 91452/ 2847 | E45: Signed SO/Pending Drawings | F45: Yes | G45: 46217 | H45: 17267.58 | I45: 15238.87 | J45: No | K45: No | L45: Not on PM board | M45: Yes | N45: Valid backlog | O45: 46251 | P45: https://panda-windows-and-doors.monday.com/boards/7469134152/pulses/12342014464
A46: Efrain Zarate | B46: Grand View Glass- Chris Medina | C46: LMAC Operable Glass Wall | D46: 89541 | E46: Signed SO/Pending Drawings | F46: Yes | G46: 46176 | H46: 17182 | I46: 13094.38 | J46: No | K46: No | L46: Pending Deposit in Invoicing | M46: Yes | N46: Valid backlog | O46: 46203 | P46: https://panda-windows-and-doors.monday.com/boards/7469134152/pulses/11362449632
A47: Efrain Zarate | B47: Elham Taherian | C47: 2180 Havensight Add On 2 | D47: 91377/2792 | E47: Signed SO/Pending Drawings | F47: Yes | G47: 46252 | H47: 14958.17 | I47: 13447.08 | J47: Yes | K47: No | L47: Not on PM board | M47: Yes | N47: Valid backlog | O47: 46280 | P47: https://panda-windows-and-doors.monday.com/boards/7469134152/pulses/12322563037
...
