Workbook

Sheet Summary
A1: Summary
A3: Count | B3: Value
A4: Data points listed | B4: =COUNTA('Field List'!C5:C65)
A5: Used on all three (Customer + Project + Estimate) | B5: =COUNTIF('Field List'!H5:H65,"All three")
A6: Shared by two records | B6: =COUNTIF('Field List'!H5:H65,"Shared*")
A7: Only on Customer | B7: =COUNTIF('Field List'!H5:H65,"Only Customer")
A8: Only on Project | B8: =COUNTIF('Field List'!H5:H65,"Only Project")
A9: Only on Estimate | B9: =COUNTIF('Field List'!H5:H65,"Only Estimate")
A10: Total used on Customer | B10: =COUNTIF('Field List'!E5:E65,"✓")
A11: Total used on Project | B11: =COUNTIF('Field List'!F5:F65,"✓")
A12: Total used on Estimate | B12: =COUNTIF('Field List'!G5:G65,"✓")
A13: Custom fields (estimate) | B13: =COUNTIF('Field List'!B5:B65,"Estimate custom field")
A14: Inputs someone has to enter per job | B14: =COUNTIF('Field List'!L5:L65,"Input*")
A15: Constants the flow fills in by itself | B15: =COUNTIF('Field List'!L5:L65,"Constant")
A16: Items you marked 'Add' | B16: =COUNTIF('Field List'!R5:R65,"Add")
A17: Items you marked 'Question' | B17: =COUNTIF('Field List'!R5:R65,"Question")
A19: How to use this file
A20: Customer / Project / Estimate columns | C20: A ✓ means the data point is written to that QBO record. One input can feed more than one record, e.g. email goes to the customer, the project, and the estimate's To address.
A21: Used in | C21: Filled in by a formula. Green = all three, blue = shared by two, blank = unique to one record.
A22: QBO field columns | C22: The exact QBO API field the flow writes on each record type. The same input often goes into a different field on each record.
A23: Value type | C23: Input = someone enters it for each job. Constant = the same every time, so the flow sets it. Lookup = found in QBO. Calculated / Rule = worked out by the flow.
A24: Required? | C24: Required = every sample used it, or QBO needs it. Recommended = most samples used it. Confirm = you need to decide.
A25: Used in the 5 sample estimates | C25: How many of 11183, 11172, 11179, 11155 and 11135 used this data point, counting the estimate, its project and its parent customer. The Estimate Comparison tab shows the actual values.
A26: Yellow cells | C26: Your input. Pick Keep / Add / Not needed / Question in 'Your review' and add comments in 'Your notes'.
A27: Light-yellow blank rows | C27: Add any data point we missed. Tick the records it belongs to and 'Used in' fills in by itself.
A29: Known API limitations
A30: • True QBO Projects (IsProject=true, ProjectRef) can't be created by a flow. Our QBO access gets 403 Forbidden from Intuit's GraphQL API (n8n execution 102). A flow can create a sub-customer (Job=true + ParentRef, execution 68).
A31: • The newer estimate custom fields (1000000019/20/22/27) weren't saved when written through the v3 API (executions 66–76). The legacy fields 1, 2 and 3 work.
A32: • The v3 API only returns line dimension names as ID numbers. We need you to tell us the names, or get GraphQL access.
A34: Sources
A35: n8n 'QBO - Master Field List Probe (read-only)' (TcfDrNFUzcyf7vLa): execution 106 = estimates 11183, 11172, 11179, 11155, 11135 plus their projects and parent customers; execution 103 = Preferences (custom field setup)
A36: n8n 'TEST-001 Custom Field Write Test' (1tF9QG7psykePj1t); 'Test Project Sub-Customer Write Test' (86wUImQUMLfMBTPy); 'QBO GraphQL Access Test' (qLRudb67GS2ldSde)
A37: n8n 'Automate Quickbook Customer & Estimation Creation' (QXxPOCPnF5oAQPD1): starter template

Sheet Field List
A1: QBO master field list – Customer / Project / Estimate
A2: Updated 2026-09-24 from estimates 11183, 11172, 11179, 11155 and 11135, plus their projects and parent customers (n8n execution 106). Only data points those estimates use are listed here. Unused ones are on the 'Excluded' tab. Terms are assumed to always be the company default. Put a ✓ in Customer / Project / Estimate for each record a data point is used on; 'Used in' fills in automatically. Yellow cells are for your review. Add any missing data points in the blank yellow rows at the bottom.
A4: # | B4: Section | C4: Data point | D4: What it's used for | E4: Customer | F4: Project | G4: Estimate | H4: Used in | I4: QBO field – Customer | J4: QBO field – Project | K4: QBO field – Estimate | L4: Value type | M4: Required? | N4: Custom field ID | O4: Used in the 5 sample estimates | P4: Example value | Q4: Notes / what the 5 estimates showed | R4: Your review | S4: Your notes
A5: 1 | B5: Customer | C5: Customer (parent) name | D5: The company the job is for. It's the name on the customer record, it links the project to its parent, and it's the first bill-to line on the estimate. | E5: ✓ | F5: ✓ | G5: ✓ | H5: =IF(COUNTA(E5:G5)=0,"",IF(COUNTA(E5:G5)=3,"All three",IF(COUNTA(E5:G5)=2,"Shared: "&IF(E5<>"","Cust ","")&IF(F5<>"","Proj ","")&IF(G5<>"","Est",""),"Only "&IF(E5<>"","Customer",IF(F5<>"","Project","Estimate"))))) | I5: DisplayName | J5: ParentRef.value (this customer's Id) | K5: BillAddr.Line1 | L5: Input | M5: Required | O5: 5/5 | P5: Integrated Door & Window Systems | Q5: Must be unique in QBO. The flow searches for it before creating a new customer. In all 5 samples the company name equals the display name.
A6: 2 | B6: Customer | C6: Company name | D6: Legal or business name. | E6: ✓ | H6: =IF(COUNTA(E6:G6)=0,"",IF(COUNTA(E6:G6)=3,"All three",IF(COUNTA(E6:G6)=2,"Shared: "&IF(E6<>"","Cust ","")&IF(F6<>"","Proj ","")&IF(G6<>"","Est",""),"Only "&IF(E6<>"","Customer",IF(F6<>"","Project","Estimate"))))) | I6: CompanyName | L6: Input | M6: Recommended | O6: 5/5 | P6: Integrated Door & Window Systems | Q6: Same as the display name in 5/5, so it can be copied instead of typed.
A7: 3 | B7: Customer | C7: Customer group (parent's parent) | D7: Only when the customer itself sits under a larger company. | E7: ✓ | H7: =IF(COUNTA(E7:G7)=0,"",IF(COUNTA(E7:G7)=3,"All three",IF(COUNTA(E7:G7)=2,"Shared: "&IF(E7<>"","Cust ","")&IF(F7<>"","Proj ","")&IF(G7<>"","Est",""),"Only "&IF(E7<>"","Customer",IF(F7<>"","Project","Estimate"))))) | I7: ParentRef + Job=true | L7: Input | M7: Optional | O7: 1/5 | P7: Turkel Design | Q7: 11155: Turkel Design → Turkel Systems → Robbins (project is 2 levels deep).
A8: 4 | B8: Customer | C8: Contact first / last name | D8: Contact person at the customer. | E8: ✓ | H8: =IF(COUNTA(E8:G8)=0,"",IF(COUNTA(E8:G8)=3,"All three",IF(COUNTA(E8:G8)=2,"Shared: "&IF(E8<>"","Cust ","")&IF(F8<>"","Proj ","")&IF(G8<>"","Est",""),"Only "&IF(E8<>"","Customer",IF(F8<>"","Project","Estimate"))))) | I8: GivenName / FamilyName | L8: Input | M8: Optional | O8: 1/5 | P8: Jamie Fronske
A9: 5 | B9: Customer | C9: Customer email(s) | D9: Where the estimate is sent. Saved on the customer and the project, and used as the estimate's To address. | E9: ✓ | F9: ✓ | G9: ✓ | H9: =IF(COUNTA(E9:G9)=0,"",IF(COUNTA(E9:G9)=3,"All three",IF(COUNTA(E9:G9)=2,"Shared: "&IF(E9<>"","Cust ","")&IF(F9<>"","Proj ","")&IF(G9<>"","Est",""),"Only "&IF(E9<>"","Customer",IF(F9<>"","Project","Estimate"))))) | I9: PrimaryEmailAddr.Address | J9: PrimaryEmailAddr.Address | K9: BillEmail.Address | L9: Input | M9: Required | O9: 5/5 | P9: Brit@idws.us | Q9: Can hold several addresses separated by commas (11155 has 3). 11179's parent email is a Panda address (shannon@), but its project/estimate use the customer's.
A10: 6 | B10: Customer | C10: Customer phone | D10: Main phone number. | E10: ✓ | H10: =IF(COUNTA(E10:G10)=0,"",IF(COUNTA(E10:G10)=3,"All three",IF(COUNTA(E10:G10)=2,"Shared: "&IF(E10<>"","Cust ","")&IF(F10<>"","Proj ","")&IF(G10<>"","Est",""),"Only "&IF(E10<>"","Customer",IF(F10<>"","Project","Estimate"))))) | I10: PrimaryPhone.FreeFormNumber | L10: Input | M10: Recommended | O10: 3/5 | P10: (310) 439-1296
A11: 7 | B11: Billing address | C11: Billing street | D11: Customer's billing address, printed as bill-to line 2 on the estimate. | E11: ✓ | G11: ✓ | H11: =IF(COUNTA(E11:G11)=0,"",IF(COUNTA(E11:G11)=3,"All three",IF(COUNTA(E11:G11)=2,"Shared: "&IF(E11<>"","Cust ","")&IF(F11<>"","Proj ","")&IF(G11<>"","Est",""),"Only "&IF(E11<>"","Customer",IF(F11<>"","Project","Estimate"))))) | I11: BillAddr.Line1 | K11: BillAddr.Line2 | L11: Input | M11: Required | O11: 5/5 | P11: 11817 Major Street | Q11: The estimate uses 3 free-form lines: company / street / 'City, ST ZIP'.
A12: 8 | B12: Billing address | C12: Billing city | E12: ✓ | G12: ✓ | H12: =IF(COUNTA(E12:G12)=0,"",IF(COUNTA(E12:G12)=3,"All three",IF(COUNTA(E12:G12)=2,"Shared: "&IF(E12<>"","Cust ","")&IF(F12<>"","Proj ","")&IF(G12<>"","Est",""),"Only "&IF(E12<>"","Customer",IF(F12<>"","Project","Estimate"))))) | I12: BillAddr.City | K12: BillAddr.Line3 | L12: Input | M12: Required | O12: 5/5 | P12: Culver City | Q12: Data quality: on Progress Glass (11179) the parent's city/state/ZIP were typed into the wrong boxes. A form with separate fields prevents this.
A13: 9 | B13: Billing address | C13: Billing state | E13: ✓ | G13: ✓ | H13: =IF(COUNTA(E13:G13)=0,"",IF(COUNTA(E13:G13)=3,"All three",IF(COUNTA(E13:G13)=2,"Shared: "&IF(E13<>"","Cust ","")&IF(F13<>"","Proj ","")&IF(G13<>"","Est",""),"Only "&IF(E13<>"","Customer",IF(F13<>"","Project","Estimate"))))) | I13: BillAddr.CountrySubDivisionCode | K13: BillAddr.Line3 | L13: Input | M13: Required | O13: 5/5 | P13: CA
A14: 10 | B14: Billing address | C14: Billing ZIP | E14: ✓ | G14: ✓ | H14: =IF(COUNTA(E14:G14)=0,"",IF(COUNTA(E14:G14)=3,"All three",IF(COUNTA(E14:G14)=2,"Shared: "&IF(E14<>"","Cust ","")&IF(F14<>"","Proj ","")&IF(G14<>"","Est",""),"Only "&IF(E14<>"","Customer",IF(F14<>"","Project","Estimate"))))) | I14: BillAddr.PostalCode | K14: BillAddr.Line3 | L14: Input | M14: Required | O14: 5/5 | P14: 90230
A15: 11 | B15: Ship-to / job site | C15: Ship-to name | D15: First ship-to line: the company name, or 'Local Pickup'. | E15: ✓ | G15: ✓ | H15: =IF(COUNTA(E15:G15)=0,"",IF(COUNTA(E15:G15)=3,"All three",IF(COUNTA(E15:G15)=2,"Shared: "&IF(E15<>"","Cust ","")&IF(F15<>"","Proj ","")&IF(G15<>"","Est",""),"Only "&IF(E15<>"","Customer",IF(F15<>"","Project","Estimate"))))) | I15: ShipAddr (default = billing) | K15: ShipAddr.Line1 | L15: Input | M15: Recommended | O15: 4/5 | P15: Local Pickup | Q15: 11155 had no name line and started with the street.
A16: 12 | B16: Ship-to / job site | C16: Ship-to street | D16: Delivery address, which is either the dealer or the job site. | E16: ✓ | G16: ✓ | H16: =IF(COUNTA(E16:G16)=0,"",IF(COUNTA(E16:G16)=3,"All three",IF(COUNTA(E16:G16)=2,"Shared: "&IF(E16<>"","Cust ","")&IF(F16<>"","Proj ","")&IF(G16<>"","Est",""),"Only "&IF(E16<>"","Customer",IF(F16<>"","Project","Estimate"))))) | I16: ShipAddr.Line1 | K16: ShipAddr.Line2 | L16: Input | M16: Required | O16: 5/5 | P16: 81-6565 Mamaka PL (Lot 235) | Q16: 3/5 shipped to the customer's own address, 1/5 was local pickup (3415 Bellington Rd.), 1/5 went to the job site. No project record had an address.
A17: 13 | B17: Ship-to / job site | C17: Ship-to city, state, ZIP | E17: ✓ | G17: ✓ | H17: =IF(COUNTA(E17:G17)=0,"",IF(COUNTA(E17:G17)=3,"All three",IF(COUNTA(E17:G17)=2,"Shared: "&IF(E17<>"","Cust ","")&IF(F17<>"","Proj ","")&IF(G17<>"","Est",""),"Only "&IF(E17<>"","Customer",IF(F17<>"","Project","Estimate"))))) | I17: ShipAddr.City / CountrySubDivisionCode / PostalCode | K17: ShipAddr.Line3 | L17: Input | M17: Required | O17: 5/5 | P17: Kealakekua, HI 96750
A18: 14 | B18: Tax | C18: Sales tax exempt? | D18: Whether the customer pays sales tax. | E18: ✓ | F18: ✓ | G18: ✓ | H18: =IF(COUNTA(E18:G18)=0,"",IF(COUNTA(E18:G18)=3,"All three",IF(COUNTA(E18:G18)=2,"Shared: "&IF(E18<>"","Cust ","")&IF(F18<>"","Proj ","")&IF(G18<>"","Est",""),"Only "&IF(E18<>"","Customer",IF(F18<>"","Project","Estimate"))))) | I18: Taxable (true/false) | J18: Taxable = false (always) | K18: Line TaxCodeRef TAX / NON | L18: Input | M18: Required | O18: 5/5 | P18: false | Q18: Parents: 2 taxable, 3 exempt. Projects were always non-taxable.
A19: 15 | B19: Tax | C19: Resale / exemption number | D19: Resale certificate number for exempt dealers. | E19: ✓ | H19: =IF(COUNTA(E19:G19)=0,"",IF(COUNTA(E19:G19)=3,"All three",IF(COUNTA(E19:G19)=2,"Shared: "&IF(E19<>"","Cust ","")&IF(F19<>"","Proj ","")&IF(G19<>"","Est",""),"Only "&IF(E19<>"","Customer",IF(F19<>"","Project","Estimate"))))) | I19: ResaleNum | L19: Input | M19: Recommended if exempt | O19: 2/5 | P19: 1037374150-001
A20: 16 | B20: Tax | C20: Customer notes | D20: Free text such as 'Sales Tax Exempt'. | E20: ✓ | H20: =IF(COUNTA(E20:G20)=0,"",IF(COUNTA(E20:G20)=3,"All three",IF(COUNTA(E20:G20)=2,"Shared: "&IF(E20<>"","Cust ","")&IF(F20<>"","Proj ","")&IF(G20<>"","Est",""),"Only "&IF(E20<>"","Customer",IF(F20<>"","Project","Estimate"))))) | I20: Notes | L20: Input | M20: Optional | O20: 3/5 | P20: Sales Tax Exempt | Q20: Avalara address validation also writes notes here automatically.
A21: 17 | B21: Tax | C21: Customer type | D21: Groups customers, e.g. dealers. | E21: ✓ | F21: ✓ | H21: =IF(COUNTA(E21:G21)=0,"",IF(COUNTA(E21:G21)=3,"All three",IF(COUNTA(E21:G21)=2,"Shared: "&IF(E21<>"","Cust ","")&IF(F21<>"","Proj ","")&IF(G21<>"","Est",""),"Only "&IF(E21<>"","Customer",IF(F21<>"","Project","Estimate"))))) | I21: CustomerTypeRef.value | J21: CustomerTypeRef.value | L21: Input | M21: Optional | O21: 1/5 | P21: 573164 | Q21: Only JDP Associates / AULT PROJECT had one.
A22: 18 | B22: Same every time | C22: Tax code | D22: Default sales tax code. | E22: ✓ | F22: ✓ | G22: ✓ | H22: =IF(COUNTA(E22:G22)=0,"",IF(COUNTA(E22:G22)=3,"All three",IF(COUNTA(E22:G22)=2,"Shared: "&IF(E22<>"","Cust ","")&IF(F22<>"","Proj ","")&IF(G22<>"","Est",""),"Only "&IF(E22<>"","Customer",IF(F22<>"","Project","Estimate"))))) | I22: DefaultTaxCodeRef | J22: DefaultTaxCodeRef | K22: TxnTaxDetail.TxnTaxCodeRef | L22: Constant | M22: Required | O22: 5/5 | P22: 999 | Q22: Tax rate 1174 at 0%. Sales tax is charged as a line item instead (see 'Sales tax line').
A23: 19 | B23: Same every time | C23: Payment terms | D23: Payment terms. | E23: ✓ | G23: ✓ | H23: =IF(COUNTA(E23:G23)=0,"",IF(COUNTA(E23:G23)=3,"All three",IF(COUNTA(E23:G23)=2,"Shared: "&IF(E23<>"","Cust ","")&IF(F23<>"","Proj ","")&IF(G23<>"","Est",""),"Only "&IF(E23<>"","Customer",IF(F23<>"","Project","Estimate"))))) | I23: SalesTermRef | K23: SalesTermRef | L23: Constant | M23: Default | O23: 0/5 set | P23: Company default (terms id 41) | Q23: Per your instruction, terms stay the same unless someone says otherwise. None of the 5 set terms on the estimate.
A24: 20 | B24: Same every time | C24: Preferred delivery method | D24: How forms are sent by default. | E24: ✓ | F24: ✓ | H24: =IF(COUNTA(E24:G24)=0,"",IF(COUNTA(E24:G24)=3,"All three",IF(COUNTA(E24:G24)=2,"Shared: "&IF(E24<>"","Cust ","")&IF(F24<>"","Proj ","")&IF(G24<>"","Est",""),"Only "&IF(E24<>"","Customer",IF(F24<>"","Project","Estimate"))))) | I24: PreferredDeliveryMethod | J24: PreferredDeliveryMethod | L24: Constant | M24: Default | O24: 5/5 | P24: Print
A25: 21 | B25: Same every time | C25: Customer message | D25: Payment-terms message printed on the estimate. | G25: ✓ | H25: =IF(COUNTA(E25:G25)=0,"",IF(COUNTA(E25:G25)=3,"All three",IF(COUNTA(E25:G25)=2,"Shared: "&IF(E25<>"","Cust ","")&IF(F25<>"","Proj ","")&IF(G25<>"","Est",""),"Only "&IF(E25<>"","Customer",IF(F25<>"","Project","Estimate"))))) | K25: CustomerMemo.value | L25: Constant | M25: Default | O25: 5/5 | P25: Our acceptable forms of payments are: ... | Q25: QBO fills in the company default.
A26: 22 | B26: Same every time | C26: Accounting email (Bcc) | D26: Copies accounting on the estimate email. | G26: ✓ | H26: =IF(COUNTA(E26:G26)=0,"",IF(COUNTA(E26:G26)=3,"All three",IF(COUNTA(E26:G26)=2,"Shared: "&IF(E26<>"","Cust ","")&IF(F26<>"","Proj ","")&IF(G26<>"","Est",""),"Only "&IF(E26<>"","Customer",IF(F26<>"","Project","Estimate"))))) | K26: BillEmailBcc.Address | L26: Constant | M26: Required | O26: 5/5 | P26: Accounting@panda-windows.com
A27: 23 | B27: Project | C27: Project / job name | D27: Name of the job. The estimate is assigned to this project. | F27: ✓ | G27: ✓ | H27: =IF(COUNTA(E27:G27)=0,"",IF(COUNTA(E27:G27)=3,"All three",IF(COUNTA(E27:G27)=2,"Shared: "&IF(E27<>"","Cust ","")&IF(F27<>"","Proj ","")&IF(G27<>"","Est",""),"Only "&IF(E27<>"","Customer",IF(F27<>"","Project","Estimate"))))) | J27: DisplayName | K27: CustomerRef.value (project Id) | L27: Input | M27: Required | O27: 5/5 | P27: Patel Entry Door | Q27: Examples: 'Billiter South', 'AULT PROJECT', 'Robbins'. The full name shows as 'Parent:Project'.
A28: 24 | B28: Project | C28: Sub-customer flag | D28: Puts the project under its parent customer. | F28: ✓ | H28: =IF(COUNTA(E28:G28)=0,"",IF(COUNTA(E28:G28)=3,"All three",IF(COUNTA(E28:G28)=2,"Shared: "&IF(E28<>"","Cust ","")&IF(F28<>"","Proj ","")&IF(G28<>"","Est",""),"Only "&IF(E28<>"","Customer",IF(F28<>"","Project","Estimate"))))) | J28: Job = true | L28: Constant | M28: Required | O28: 5/5 | P28: true
A29: 25 | B29: Project | C29: Bill with parent | D29: Sends the project's bills to the parent. | F29: ✓ | H29: =IF(COUNTA(E29:G29)=0,"",IF(COUNTA(E29:G29)=3,"All three",IF(COUNTA(E29:G29)=2,"Shared: "&IF(E29<>"","Cust ","")&IF(F29<>"","Proj ","")&IF(G29<>"","Est",""),"Only "&IF(E29<>"","Customer",IF(F29<>"","Project","Estimate"))))) | J29: BillWithParent = true | L29: Constant | M29: Required | O29: 5/5 | P29: true
A30: 26 | B30: Project | C30: QBO Project link | D30: Links the estimate to the QBO Project. | F30: ✓ | G30: ✓ | H30: =IF(COUNTA(E30:G30)=0,"",IF(COUNTA(E30:G30)=3,"All three",IF(COUNTA(E30:G30)=2,"Shared: "&IF(E30<>"","Cust ","")&IF(F30<>"","Proj ","")&IF(G30<>"","Est",""),"Only "&IF(E30<>"","Customer",IF(F30<>"","Project","Estimate"))))) | J30: IsProject = true | K30: ProjectRef.value | L30: Lookup | M30: Required | O30: 5/5 | P30: 813422277 | Q30: All 5 are true QBO Projects. A flow can't create one with our current QBO access (403 Forbidden). The Project has to be made in QBO first, then the flow finds it.
A31: 27 | B31: Estimate | C31: Estimate # | D31: Estimate number. | G31: ✓ | H31: =IF(COUNTA(E31:G31)=0,"",IF(COUNTA(E31:G31)=3,"All three",IF(COUNTA(E31:G31)=2,"Shared: "&IF(E31<>"","Cust ","")&IF(F31<>"","Proj ","")&IF(G31<>"","Est",""),"Only "&IF(E31<>"","Customer",IF(F31<>"","Project","Estimate"))))) | K31: DocNumber | L31: Input / next # | M31: Required | O31: 5/5 | P31: 11172
A32: 28 | B32: Estimate | C32: Estimate date | D32: Date the estimate was issued. | G32: ✓ | H32: =IF(COUNTA(E32:G32)=0,"",IF(COUNTA(E32:G32)=3,"All three",IF(COUNTA(E32:G32)=2,"Shared: "&IF(E32<>"","Cust ","")&IF(F32<>"","Proj ","")&IF(G32<>"","Est",""),"Only "&IF(E32<>"","Customer",IF(F32<>"","Project","Estimate"))))) | K32: TxnDate | L32: Input | M32: Required | O32: 5/5 | P32: 2026-09-14
A33: 29 | B33: Estimate | C33: Sales rep email(s) (Cc) | D33: Copies the sales rep(s) on the estimate email. | G33: ✓ | H33: =IF(COUNTA(E33:G33)=0,"",IF(COUNTA(E33:G33)=3,"All three",IF(COUNTA(E33:G33)=2,"Shared: "&IF(E33<>"","Cust ","")&IF(F33<>"","Proj ","")&IF(G33<>"","Est",""),"Only "&IF(E33<>"","Customer",IF(F33<>"","Project","Estimate"))))) | K33: BillEmailCc.Address | L33: Input | M33: Required | O33: 5/5 | P33: seant@panda-windows.com | Q33: 2/5 had several reps (e.g. efrain, trevorb, dmccall). This field is how a rep is tied to an estimate. The Sales Rep custom field isn't used.
A34: 30 | B34: Estimate custom field | C34: Q Number / PO # | D34: The company's Q number. | G34: ✓ | H34: =IF(COUNTA(E34:G34)=0,"",IF(COUNTA(E34:G34)=3,"All three",IF(COUNTA(E34:G34)=2,"Shared: "&IF(E34<>"","Cust ","")&IF(F34<>"","Proj ","")&IF(G34<>"","Est",""),"Only "&IF(E34<>"","Customer",IF(F34<>"","Project","Estimate"))))) | K34: CustomField DefinitionId 1 | L34: Input | M34: Recommended | N34: 1 (legacy) | O34: 4/5 | P34: 92437 | Q34: Missing only on 11183.
A35: 31 | B35: Estimate custom field | C35: Deposit Due | D35: Deposit amount the customer owes. | G35: ✓ | H35: =IF(COUNTA(E35:G35)=0,"",IF(COUNTA(E35:G35)=3,"All three",IF(COUNTA(E35:G35)=2,"Shared: "&IF(E35<>"","Cust ","")&IF(F35<>"","Proj ","")&IF(G35<>"","Est",""),"Only "&IF(E35<>"","Customer",IF(F35<>"","Project","Estimate"))))) | K35: CustomField DefinitionId 3 | L35: Input | M35: Required | N35: 3 (legacy) | O35: 5/5 | P35: $12,958.31 | Q35: Free text. It can carry notes, e.g. '$52,988.75 - 50% Dep.' or "CO#1 Deposit Req'd $2,883.90".
A36: 32 | B36: Product lines | C36: Product / Service | D36: The product being sold. | G36: ✓ | H36: =IF(COUNTA(E36:G36)=0,"",IF(COUNTA(E36:G36)=3,"All three",IF(COUNTA(E36:G36)=2,"Shared: "&IF(E36<>"","Cust ","")&IF(F36<>"","Proj ","")&IF(G36<>"","Est",""),"Only "&IF(E36<>"","Customer",IF(F36<>"","Project","Estimate"))))) | K36: Line.SalesItemLineDetail.ItemRef | L36: Input | M36: Required | O36: 5/5 | P36: Voyage Collection:Voyage Col | Q36: Seen: Folding Door System (FTS.60, FUTS.60), Hinged Doors, Sidelites & Transoms, Voyage Collection, Lift & Slides.
A37: 33 | B37: Product lines | C37: Line description | D37: Text describing the product. | G37: ✓ | H37: =IF(COUNTA(E37:G37)=0,"",IF(COUNTA(E37:G37)=3,"All three",IF(COUNTA(E37:G37)=2,"Shared: "&IF(E37<>"","Cust ","")&IF(F37<>"","Proj ","")&IF(G37<>"","Est",""),"Only "&IF(E37<>"","Customer",IF(F37<>"","Project","Estimate"))))) | K37: Line.Description | L37: Input | M37: Required | O37: 5/5 | P37: Voyage Collection Pivot Door | Q37: Change orders add 'CO#1' to the description.
A38: 34 | B38: Product lines | C38: Quantity | D38: Number of units. | G38: ✓ | H38: =IF(COUNTA(E38:G38)=0,"",IF(COUNTA(E38:G38)=3,"All three",IF(COUNTA(E38:G38)=2,"Shared: "&IF(E38<>"","Cust ","")&IF(F38<>"","Proj ","")&IF(G38<>"","Est",""),"Only "&IF(E38<>"","Customer",IF(F38<>"","Project","Estimate"))))) | K38: Line.SalesItemLineDetail.Qty | L38: Input | M38: Required | O38: 5/5 | P38: 1 | Q38: Can be 0 for items taken off in a change order (11135).
A39: 35 | B39: Product lines | C39: Rate | D39: Price per unit. | G39: ✓ | H39: =IF(COUNTA(E39:G39)=0,"",IF(COUNTA(E39:G39)=3,"All three",IF(COUNTA(E39:G39)=2,"Shared: "&IF(E39<>"","Cust ","")&IF(F39<>"","Proj ","")&IF(G39<>"","Est",""),"Only "&IF(E39<>"","Customer",IF(F39<>"","Project","Estimate"))))) | K39: Line.SalesItemLineDetail.UnitPrice | L39: Input | M39: Required | O39: 5/5 | P39: 23671.61 | Q39: A $0 rate is used for add-on pieces like sidelites (11172).
A40: 36 | B40: Product lines | C40: Amount | D40: Line total, Qty × Rate. | G40: ✓ | H40: =IF(COUNTA(E40:G40)=0,"",IF(COUNTA(E40:G40)=3,"All three",IF(COUNTA(E40:G40)=2,"Shared: "&IF(E40<>"","Cust ","")&IF(F40<>"","Proj ","")&IF(G40<>"","Est",""),"Only "&IF(E40<>"","Customer",IF(F40<>"","Project","Estimate"))))) | K40: Line.Amount | L40: Calculated | M40: Required | O40: 5/5 | P40: 23671.61
A41: 37 | B41: Product lines | C41: Line tax code | D41: Whether the line is taxed. | G41: ✓ | H41: =IF(COUNTA(E41:G41)=0,"",IF(COUNTA(E41:G41)=3,"All three",IF(COUNTA(E41:G41)=2,"Shared: "&IF(E41<>"","Cust ","")&IF(F41<>"","Proj ","")&IF(G41<>"","Est",""),"Only "&IF(E41<>"","Customer",IF(F41<>"","Project","Estimate"))))) | K41: Line.SalesItemLineDetail.TaxCodeRef | L41: Rule | M41: Required | O41: 5/5 | P41: TAX | Q41: Products, crating, soft wrap and the deposit line are TAX. Shipping and the sales tax line are NON.
...

Sheet Estimate Comparison
A1: Estimate comparison – what each estimate actually uses
A2: Values come from QBO (n8n execution 106). A blank cell means that estimate, its project or its customer didn't use the data point. 'Used (of 5)' is a formula.
A4: Data point | B4: Est 11183 | C4: Est 11172 | D4: Est 11179 | E4: Est 11155 | F4: Est 11135 | G4: Used (of 5)
A5: CUSTOMER (parent)
A6: Customer (parent) name | B6: Ajay Glass & Mirror Co., Inc. | C6: Integrated Door & Window Systems | D6: Progress Glass | E6: Turkel Systems | F6: JDP Associates | G6: =COUNTA(B6:F6)
A7: Company name | B7: Ajay Glass & Mirror Co., Inc. | C7: Integrated Door & Window Systems | D7: Progress Glass | E7: Turkel Systems | F7: JDP Associates | G7: =COUNTA(B7:F7)
A8: Customer group (parent's parent) | E8: Turkel Design | G8: =COUNTA(B8:F8)
A9: Contact first / last name | E9: Jamie Fronske | G9: =COUNTA(B9:F9)
A10: Customer email(s) | B10: Gsonneville@ajayglass.com | C10: Brit@idws.us | D10: shannon@panda-windows.com (parent) / LuisCuestas@progressglass.com (project + estimate) | E10: ap@turkelsystems.com (+ jamie@, Jake@turkeldesign.com on the project and estimate) | F10: Joey@adc.vegas | G10: =COUNTA(B10:F10)
A11: Customer phone | C11: (310) 439-1296 | E11: 905-782-7372 | F11: 702-812-8566 | G11: =COUNTA(B11:F11)
A12: Billing street | B12: 5786 Collett Road | C12: 11817 Major Street | D12: 25 Patterson Street | E12: 1060 Broadway Ste C102 | F12: 3 Hunt Valley Trail | G12: =COUNTA(B12:F12)
A13: Billing city, state, ZIP | B13: Farmington, NY 14425 | C13: Culver City, CA 90230 | D13: San Francisco, CA 94124 (typed into the wrong fields) | E13: Somerville, MA 02144 | F13: Henderson, NV 89052 | G13: =COUNTA(B13:F13)
A14: Sales tax exempt? | B14: No (taxable) | C14: Yes | D14: No (taxable) | E14: Yes | F14: Yes | G14: =COUNTA(B14:F14)
A15: Resale / exemption number | E15: 709371904 | F15: 1037374150-001 | G15: =COUNTA(B15:F15)
A16: Customer notes | C16: Avalara validation | D16: Avalara validation | E16: Sales Tax Exempt | F16: Sales Tax Exempt | G16: =COUNTA(B16:F16)
A17: Customer type | F17: 573164 | G17: =COUNTA(B17:F17)
A18: PROJECT
A19: Project / job name | B19: Billiter South | C19: Patel Entry Door | D19: Marin Art & Garden Center | E19: Robbins | F19: AULT PROJECT | G19: =COUNTA(B19:F19)
A20: True QBO Project (ProjectRef) | B20: 813951180 | C20: 813422277 | D20: 813787820 | E20: 812691046 | F20: 812079306 | G20: =COUNTA(B20:F20)
A21: Sub-customer / bill with parent / non-taxable | B21: Yes | C21: Yes | D21: Yes | E21: Yes | F21: Yes | G21: =COUNTA(B21:F21)
A22: Project address | G22: =COUNTA(B22:F22)
A23: ESTIMATE HEADER
A24: Estimate date | B24: 2026-09-18 | C24: 2026-09-14 | D24: 2026-09-17 | E24: 2026-09-08 | F24: 2026-09-02 | G24: =COUNTA(B24:F24)
A25: Bill-to (as printed) | B25: Ajay Glass & Mirror Co., Inc. / 5786 Collett Road / Farmington, NY 14425 | C25: Integrated Door & Window Systems / 11817 Major Street / Culver City, CA 90230 | D25: Progress Glass Company, Inc. / 25 Patterson Street / San Francisco CA 94124 | E25: Turkel Systems / 1060 Broadway Ste C102 / Somerville, MA 02144 | F25: JDP Associates / 3 Hunt Valley Trail / Henderson, NV 89052 | G25: =COUNTA(B25:F25)
A26: Ship-to (as printed) | B26: Ajay Glass & Mirror Co., Inc. / 5786 Collett Road / Farmington, NY 144255 | C26: Integrated Door & Window Systems / 11817 MAJOR ST / CULVER CITY, CA 902306332 | D26: Progress Glass / 25 Patterson Street / San Francisco CA 94124 | E26: 81-6565 Mamaka PL (Lot 235) / Kealakekua, HI 96750 (job site) | F26: Local Pickup / 3415 Bellington Rd. / North Las Vegas, NV 89030 | G26: =COUNTA(B26:F26)
A27: To email | B27: Gsonneville@ajayglass.com | C27: Brit@idws.us | D27: LuisCuestas@progressglass.com | E27: ap@turkelsystems.com, jamie@turkeldesign.com, Jake@turkeldesign.com | F27: Joey@adc.vegas | G27: =COUNTA(B27:F27)
A28: Sales rep email(s) (Cc) | B28: stefan@ | C28: seant@ | D28: dmccall@ | E28: efrain@, trevorb@, dmccall@ | F28: trevorb@, efrain@ | G28: =COUNTA(B28:F28)
A29: Accounting email (Bcc) | B29: Accounting@ | C29: Accounting@ | D29: Accounting@ | E29: Accounting@ | F29: Accounting@ | G29: =COUNTA(B29:F29)
A30: Customer message | B30: Default | C30: Default | D30: Default | E30: Default | F30: Default | G30: =COUNTA(B30:F30)
A31: Terms / expiration / memo | G31: =COUNTA(B31:F31)
A32: Q Number / PO # | C32: 92437 | D32: 91229 | E32: 89724 | F32: 89465 | G32: =COUNTA(B32:F32)
A33: Deposit Due | B33: $14,835.63 | C33: $12,958.31 | D33: $49,156.80 | E33: $52,988.75 - 50% Dep. | F33: CO#1 Deposit Req'd $2,883.90 | G33: =COUNTA(B33:F33)
A34: LINE ITEMS
A35: Products | B35: Folding Door System:FTS.60 | C35: Voyage Collection: Voyage Col, Voyage Col Sidelite | D35: Folding Door System:FUTS.60 | E35: Lift & Slides:LIS.14 | F35: Hinged Doors FDS.21/FDTS.64, Sidelites S.21, Folding FTS.60 | G35: =COUNTA(B35:F35)
A36: # product lines | B36: 1 | C36: 3 | D36: 4 | E36: 3 | F36: 9 | G36: =COUNTA(B36:F36)
A37: Line dimensions (3 per product line) | B37: Yes | C37: Yes | D37: Yes | E37: Yes | F37: Yes | G37: =COUNTA(B37:F37)
A38: Change order (CO#) lines | F38: CO#1 (4 lines at qty 0) | G38: =COUNTA(B38:F38)
A39: Crating fee | B39: 1080 | C39: 480 | D39: 2460 | E39: 1843 | G39: =COUNTA(B39:F39)
A40: Shipping fee | B40: 4655.35 | C40: 1765 | D40: 4816.25 | E40: 11500 | G40: =COUNTA(B40:F40)
A41: Sales tax line | B41: 1876.19 | D41: 8064.16 | G41: =COUNTA(B41:F41)
...

Sheet Intake Table Gap
A1: QBO Estimate Intake (n8n data table) vs. the field list
A2: Compares data table Z3FW8RjSWUyDcIBl (29 columns, 0 rows as of 2026-09-24) to the 46 data points on the Field List tab. Status counts are formulas.
A4: Field List data point | B4: Intake table column | C4: Status | D4: Note | E4: Your decision | G4: Status | H4: Count
A5: Customer (parent) name | B5: customer_name | C5: Match | G5: Match (incl. output) | H5: =COUNTIF($C$5:$C$62,"Match*")
A6: Company name | B6: customer_company | C6: Match | G6: Partial | H6: =COUNTIF($C$5:$C$62,"Partial")
A7: Customer group (parent's parent) | C7: Missing | D7: Only needed when the parent is under a larger company (1/5). | G7: Missing | H7: =COUNTIF($C$5:$C$62,"Missing")
A8: Contact first / last name | C8: Missing | D8: Optional (1/5). | G8: Set by flow | H8: =COUNTIF($C$5:$C$62,"Set by flow")
A9: Customer email(s) | B9: customer_email | C9: Match | D9: Allow several addresses separated by commas. | G9: In table, not on list | H9: =COUNTIF($C$5:$C$62,"In table, not on list")
A10: Customer phone | B10: customer_phone | C10: Match | G10: Tracking column | H10: =COUNTIF($C$5:$C$62,"Tracking column")
A11: Billing street | C11: Missing | D11: Used 5/5. Needed to create a new customer and for the estimate bill-to.
A12: Billing city | C12: Missing | D12: Used 5/5.
A13: Billing state | C13: Missing | D13: Used 5/5.
A14: Billing ZIP | C14: Missing | D14: Used 5/5.
A15: Ship-to name | C15: Missing | D15: Used 4/5. Company name or 'Local Pickup'.
A16: Ship-to street | C16: Missing | D16: Used 5/5. Job site, the dealer's address, or Local Pickup.
A17: Ship-to city, state, ZIP | C17: Missing | D17: Used 5/5.
A18: Sales tax exempt? | C18: Missing | D18: Used 5/5. Decides whether a Sales Tax fee line is added. (tax_code looks like the per-line TAX/NON code.)
A19: Resale / exemption number | C19: Missing | D19: Used 2/5, on exempt customers.
A20: Customer notes | C20: Missing | D20: Optional (3/5).
A21: Customer type | C21: Missing | D21: Optional (1/5).
A22: Tax code | C22: Set by flow | D22: Always 999. Doesn't need a column.
... A26: Accounting email (Bcc) | C26: Set by flow | D26: Always Accounting@panda-windows.com.
A27: Project / job name | B27: project_name | C27: Match
A28: Sub-customer flag | C28: Set by flow | D28: Always true.
A29: Bill with parent | C29: Set by flow | D29: Always true.
A30: QBO Project link | B30: project_ref_id / native_project_id | C30: Match (output) | D30: The flow writes these back. The true Project still has to be created in QBO first.
A31: Estimate # | B31: doc_number (input) / estimate_doc_number (output) | C31: Match
A32: Estimate date | C32: Missing | D32: Used 5/5. The flow could default to today, but the dates on the samples were all different.
A33: Sales rep email(s) (Cc) | C33: Missing | D33: Used 5/5, and it's how reps are tied to estimates. rsm and outside_sales_rep hold names, not the Cc email.
A34: Q Number / PO # | B34: q_number_po | C34: Match
A35: Deposit Due | B35: deposit_due | C35: Match | D35: Free text.
A36: Product / Service | B36: item_ref_id + line_items_json | C36: Partial | D36: The item_* columns hold only ONE line. The samples had 3–13 lines, so line_items_json has to carry them.
A37: Line description | B37: item_description + line_items_json | C37: Partial | D37: Same as above.
A38: Quantity | B38: item_qty + line_items_json | C38: Partial | D38: Same as above.
A39: Rate | B39: item_unit_price + line_items_json | C39: Partial | D39: Same as above.
A40: Amount | B40: item_amount + line_items_json | C40: Partial | D40: Could be calculated as qty × rate.
A41: Line tax code | B41: tax_code + line_items_json | C41: Partial | D41: Needs a value per line (TAX vs NON).
A42: Line dimension 1000000039 | B42: (line_items_json?) | C42: Missing | D42: On every product line. No column, and the JSON layout isn't defined.
A43: Line dimension 1000000051 | B43: (line_items_json?) | C43: Missing | D43: Same as above.
A44: Line dimension 1000000172 | B44: (line_items_json?) | C44: Missing | D44: Same as above.
...

Sheet Excluded
A1: Not used by the 5 estimates (taken off the main list)
A2: To bring one back, choose 'Add back' in column D. It's then worth copying the item to a blank row on the Field List tab.
A4: Data point | B4: Record | C4: Why excluded | D4: Your decision
A5: Mobile phone | B5: Customer | C5: 0/5
A6: Ship-from address | B6: Estimate | C6: 0/5
A7: Project address / start-end dates / status | B7: Project | C7: 0/5 (and dates can't be set through the API)
A8: Expiration date | B8: Estimate | C8: 0/5
A9: Internal memo (PrivateNote) | B9: Estimate | C9: 0/5
A10: Class / Location | B10: Estimate | C10: 0/5
A11: Service date on lines | B11: Estimate | C11: 0/5
A12: Discount line | B12: Estimate | C12: 0/5 (1 of the earlier 10 had one)
A13: QBO shipping field (ShipAmt) / QBO deposit field | B13: Estimate | C13: 0/5. Shipping and deposit are handled as fee lines and the Deposit Due field.
A14: Sales Rep custom field (legacy #2) | B14: Estimate | C14: 0/5. Reps are tracked with the Cc email.
A15: Residential or Commercial / Dealer / Outside Sales Rep / RSM (newer custom fields) | B15: Estimate | C15: Can't be read or written through our current API. If your team fills these in on screen, move them back to the main list.
A16: Accepted date / status / linked invoice | B16: Estimate | C16: QBO sets these after the estimate is created (4/5 were converted to invoices).
